Workbook

Sheet README
A1: IDR Prep Studio v4 – Build Spec
A3: Version | B3: 4.0
A4: Date | B4: 2026-10-26
A5: Audience | B5: IT and software development, and the Studio admins (sheet "Configuration guide").
A6: Purpose | B6: Build spec for IDR Prep Studio v4. v4 moves configuration and access into the Sheet: every list on Options (with Key, Sort, Strict), a Fields tab merged into the schema, a Users tab with roles checked on the server, a BillingEntities tab, RCM Specialist (was Owner), and upload before saving.
A7: Reference | B7: This workbook matches the finished v4 code (idr-prep-studio/Code.gs and README.md). Field rows, Options and BillingEntities seed rows and tab columns are dumped from Code.gs by dump_code.js. Where spec-studio-v4.md and the code differ, the code wins.
A8: Source (portal rules) | B8: "IDR Gateway Notice of IDR Initiation User Guide, Version 15.0, October 14, 2026". Portal labels, option texts, format rules and messages are quoted from that guide. Sheet "Guide changes" maps each guide section to the Studio.
A9: Other sources | B9: spec-studio-v4.md (on top of v3 and v2). Seed lists from the business: 24 billing entities, 124 non-initiating parties (payers), 373 service codes. Trends and Observed lines: the 4 real notices used for v2 (DISP-7984427, DISP-7986216, DISP-7997846, DISP-7998956).
A10: Fixed business facts | B10: 1. We always initiate (provider or facility); plan/issuer paths are not built. 2. q_acting_as is "Health care provider" or "Health care facility" only. 3. Location of service is always TX (Fixed + Locked on the Fields tab).
A11: Timing count | B11: The ON start date is business day 1; b counts both days. Day 30 ends open negotiation; days 31–34 are the window; after 34 an extension reason is needed. Before day 31 a dispute can go to the US desk ("Not open yet"); Start portal entry and Mark as filed wait.
A12: Roles | B12: Admin, LB Member (Lebanon preparers), US Member (US desk). Only active rows on the Users tab can open the app; every server function checks the role. See "Roles & permissions".
A13: Configuration | B13: Admins change lists, fields, settings, users and billing entities in the app (Admin screens) or on the tabs. See "Configuration guide" for which tab and column to edit.
A14: Not the CMS portal | B14: The Studio never connects to the federal IDR portal or the IDR Gateway. The US desk copies values by hand. Keep the "not the CMS portal" banner.
... A18: How to use | B18: 1. Configuration guide: for admins, which tab and column to edit for each change.
B19: 2. Fields: every field as the Fields tab seeds it, with portal page, guide label, rules and notes. Rows marked "In Fields tab? No" are Studio-only (US desk tracking, derived or display).
B20: 3. Lists (Options seed, 637 rows), Payers, BillingEntities (tab seed) and ServiceCodes hold the seed data.
B21: 4. Validation rules, Workflow, Roles & permissions and Learning rules are the requirements. Cite the IDs.
B22: 5. Data model (all tabs and columns, Settings keys) and API (server functions) describe the build.
B23: 6. Backlog, Open questions and Guide changes. Trends and Observed lines show the 4 v2 notices.
A24: Formulas | B24: ServiceCodes (Times seen, QPA min and max) and Trends (Share) use formulas over Observed lines.
A25: Version legend | B25: v2, v3, v4 = the version that added the item; "(changed)" = changed in that version; Removed = dropped; Not built = shown by the portal but never applies to us.
A26: Dispute statuses | B26: Draft, Ready for US desk, Returned, Filed. IDRE selection is tracked in idre_final and idre_status. Ready disputes before business day 31 are grouped under "Not open yet".
A27: Orange cells | B27: A flag: a data-quality finding, a guess to confirm, or a value that needs a business answer.
A28: Grey rows | B28: Not built, Removed, Studio-only or answered rows.
A29: Sheets | B29: README, Configuration guide, Fields, Lists, Payers, BillingEntities, ServiceCodes, Trends, Observed lines, Learning rules, Validation rules, Workflow, Roles & permissions, Data model, API, Backlog, Open questions, Guide changes.

Sheet Configuration guide
A1: Area | B1: Change you want | C1: Where in the app | D1: Tab | E1: Column(s) | F1: How | G1: Takes effect | H1: Notes / limits
A2: People | B2: Add a member, or give access | C2: Admin -> Users | D2: Users | E2: Email, Name, Role, Team, Active | F2: Add a row (Active Yes). Role: Admin, LB Member or US Member. | G2: Within 2 minutes | H2: Never delete a row.
A3: People | B3: Change a role or team | C3: Admin -> Users | D3: Users | E3: Role, Team | F3: Edit the row. | G3: Within 2 minutes | H3: The last active Admin cannot be demoted.
A4: People | B4: Remove access | C4: Admin -> Users | D4: Users | E4: Active | F4: Set Active to No. | G4: Within 2 minutes | H4: Rows are never deleted (history).
A5: Lists | B5: Add a payer or IDR entity, or fix its contact | C5: Admin -> Lists (or let users learn it) | D5: Options | E5: List, Value, Data (JSON for payer address, email, phone, fax) | F5: Add or edit a row; Status Active. | G5: Within 10 minutes (or at once from the app) | H5: Payer names must use the portal name characters.
A6: Lists | B6: Hide a value, or merge a duplicate | C6: Admin -> Lists | D6: Options | E6: Status / merge | F6: Hide, or merge the learned value into the right one. | G6: At once | H6: Hidden values are never suggested.
A7: Lists | B7: CMS rewords a portal option | C7: Admin -> Lists | D7: Options | E7: Value (keep Key) | F7: Reword the Value. Never change the Key. | G7: At once | H7: Strict lists: HealthPlanType, PlanRole, ActingAs, ExtensionReason, ItemType, DisputeType, LineType, YesNo, BundledPayment, NipMethod, IdreStatus.
A8: Lists | B8: Change the order of a portal list | C8: Admin -> Lists | D8: Options | E8: Sort | F8: Set Sort numbers. | G8: At once
A9: Lists | B9: Add a service code description | C9: Admin -> Lists (or first save) | D9: Options | E9: Label (ServiceCode) | F9: Type the description. | G9: At once | H9: Code must be 5 letters or digits.
A10: Lists | B10: Add next year's holidays (each December) | C10: Sheet | D10: Options | E10: List Holiday, Value YYYY-MM-DD, Label | F10: Add one row per federal holiday. | G10: Within 10 minutes | H10: The timing rules use them.
A11: Lists | B11: Add a modifier, POS code or return reason | C11: Admin -> Lists (or learned) | D11: Options | E11: List, Value, Label | F11: Add a row. | G11: At once
A12: Billing entities | B12: Add or complete a billing entity | C12: Admin -> Billing entities | D12: BillingEntities | E12: Name, ActingAs, TIN, NPI, GroupName, Addr1, City, State, ZIP, Email, Phone, Fax | F12: Fill the columns; set Confirmed Yes once checked. | G12: At once | H12: Checks: TIN 9, NPI 10, ZIP, phone, email, portal characters.
A13: Billing entities | B13: Rename or record an old spelling | C13: Admin -> Billing entities | D13: BillingEntities | E13: Name, Aliases | F13: Rename (the old name goes into Aliases) or add to Aliases (semicolon list). | G13: At once
A14: Billing entities | B14: Hide an entity | C14: Admin -> Billing entities | D14: BillingEntities | E14: Status | F14: Hidden. | G14: At once
A15: Fields | B15: Change a label or help text | C15: Admin -> Settings & fields | D15: Fields | E15: Label, Help | F15: Edit the row. | G15: Within 10 minutes (at once from the app) | H15: Keep the portal wording for portal fields.
A16: Fields | B16: Make a field required or optional | C16: Admin -> Settings & fields | D16: Fields | E16: Required | F16: Yes or No. | G16: At once | H16: Rule fields (portal logic) cannot be changed.
A17: Fields | B17: Change a default | C17: Admin -> Settings & fields | D17: Fields | E17: Default, DefaultMode | F17: Fixed = always Default; Learned = most used recent value, else Default; None. Tokens @top, @me, @myteam. | G17: At once | H17: A default must be an option of its list.
A18: Fields | B18: Lock or hide a field, or change the order | C18: Admin -> Settings & fields | D18: Fields | E18: Locked, Visible, Order | F18: Edit the row. | G18: At once | H18: A required field cannot be hidden.
A19: Fields | B19: Change a format check or the copy order | C19: Sheet | D19: Fields | E19: Pattern, PatternMessage, CopyOrder | F19: Edit the row (regex for Pattern). | G19: Within 10 minutes | H19: An invalid pattern is ignored with a warning.
A20: Settings | B20: Learning on or off | C20: Admin -> Settings & fields | D20: Settings | E20: LearningMode | F20: On or Off. | G20: At once | H20: Off: new values wait as Hidden.
A21: Settings | B21: Learned default sensitivity | C21: Admin -> Settings & fields | D21: Settings | E21: DefaultWindow, DefaultShare | F21: Numbers (50; 0.8). | G21: At once
A22: Settings | B22: Complex State list | C22: Admin -> Settings & fields | D22: Settings | E22: ComplexStates | F22: Codes like TX, NM. | G22: At once | H22: Open question: is TX on the list?
A23: Settings | B23: File limits | C23: Admin -> Settings & fields | D23: Settings | E23: MaxFileMb, DisputeMaxMb | F23: At most 45 and 500. | G23: At once
A24: Settings | B24: Gateway banner and portal timer | C24: Admin -> Settings & fields | D24: Settings | E24: GatewayFrom, GatewayBannerUntil, PortalSessionMinutes, PortalWarnMinutes | F24: Dates YYYY-MM-DD; minutes. | G24: At once
A25: Settings | B25: Staged upload cleanup | C25: Admin -> Settings & fields; editor | D25: Settings | E25: StagingDays | F25: Days (1-90). Run installTriggers once for the daily cleanup. | G25: Next cleanup
A26: Do not edit by hand | B26: Dispute data | C26: - | D26: Disputes, LineItems, Files, Log | E26: - | F26: Use the app. Never edit Keys, DisputeIDs, FileIds or the Log. | G26: - | H26: Edits outside the app skip the checks and the Log.
A27: After a code update | B27: New fields or lists | C27: Editor | D27: all | E27: - | F27: Run setup (safe to run again). | G27: At once | H27: setup never changes existing Fields rows (Open questions Q29).

Sheet Fields
A1: Portal page | B1: Guide § | C1: Page (Fields tab) | D1: Section | E1: Order | F1: Key | G1: Label (Fields tab seed = Code.gs) | H1: Portal label (guide v15) | I1: Help | J1: Type | K1: List | L1: Required | M1: Default | N1: DefaultMode | O1: Locked | P1: Visible | Q1: Pattern | R1: PatternMessage | S1: CopyOrder | T1: Validation rule | U1: Auto-fill from | V1: Version | W1: Notes | X1: In Fields tab?
A2: Dispute header (Studio only) | B2: - | C2: internal | D2: Internal | E2: 1 | F2: Team | G2: Team | H2: (not on the portal) | J2: combo | K2: Team | L2: No | M2: @myteam | N2: Fixed | O2: No | P2: Yes | T2: Typo check (V31). | V2: v4 (changed) | W2: Learned on save; no seed. v4: searchable box with "Add new" (name characters). Default @myteam = the signed-in user's Team on the Users tab. New values join the Team list on save. | X2: Yes
A3: Dispute header (Studio only) | B3: - | C3: internal | D3: Internal | E3: 2 | F3: RcmSpecialist | G3: RCM Specialist | H3: (not on the portal) | J3: combo | K3: RcmSpecialist | L3: No | M3: @me | N3: Fixed | O3: No | P3: Yes | V3: v4 (changed) | W3: v4: was Owner. Searchable box with "Add new": suggestions = active Users (email or name) + the RcmSpecialist list; a new value must be a valid email and joins the list on save. Default @me = the signed-in LB Member's email. | X3: Yes
A4: 1 · Introduction & Qualification Questions | B4: 1.3 (2) | C4: qual | E4: 1 | F4: q_prior_2022 | G4: Was the service in question provided prior to 1/1/2022? | H4: *Was the service in question provided prior to 1/1/2022? | J4: radio | K4: YesNo | L4: Yes | M4: No | N4: Learned | O4: No | P4: Yes | T4: Yes or No. Yes = hard stop with the portal alert (V11). | V4: v2 | W4: Guide: if the plan renewal date for plan year 2022 is after the date of service, the dispute is not eligible. | X4: Yes
A5: 1 · Introduction & Qualification Questions | B5: 1.3 (3) | C5: qual | E5: 2 | F5: q_acting_as | G5: I am (or I am acting on behalf of) a: | H5: *I am (or I am acting on behalf of) a: | J5: radio | K5: ActingAs | L5: Yes | N5: None | O5: No | P5: Yes | T5: One of the 2 ActingAs values (V39). | U5: BillingEntity.acting_as | V5: v3 (changed) | W5: Portal shows 6 options; we only use "Health care provider" or "Health care facility" (fixed business fact). Locked chip filled from the billing entity; "guess from the name: check it" chip while BillingEntities Confirmed = No. | X5: Yes
A6: 1 · Introduction & Qualification Questions | B6: 1.3 (4a) | C6: qual | E6: 3 | F6: tin | G6: Tax ID: | H6: * Tax ID | J6: text | L6: Rule | N6: None | O6: No | P6: Yes | Q6: ^\d{9}$ | R6: must be 9 digits | T6: ^\d{9}$ when filled (V09). At least one of tin / npi (V38). | U6: BillingEntity.tin | V6: v3 (changed) | W6: Required depends on other answers (portal rule in code) Guide: "The initiating party must complete at least one of the two fields." TIN must be nine digits. | X6: Yes
A7: 1 · Introduction & Qualification Questions | B7: 1.3 (4b) | C7: qual | E7: 4 | F7: npi | G7: National Provider Identifier (NPI): | H7: * National Provider Identifier (NPI) | J7: text | L7: Rule | N7: None | O7: No | P7: Yes | Q7: ^\d{10}$ | R7: must be 10 digits | T7: ^\d{10}$ when filled (V10). At least one of tin / npi (V38). | U7: BillingEntity.npi | V7: v3 (changed) | W7: Required depends on other answers (portal rule in code) NPI must be ten digits. | X7: Yes
A8: 1 · Introduction & Qualification Questions | B8: 1.3 (5) | C8: qual | E8: 5 | F8: q_plan_type | G8: Health Plan Type: | H8: *Health Plan Type | I8: Not eligible if the member is only enrolled in coverage such as Medicare, Medicaid, CHIP, TRICARE or a health care sharing ministry. | J8: select | K8: HealthPlanType | L8: Yes | M8: Either partially or fully self-insured ERISA group health plan | N8: Learned | O8: No | P8: Yes | T8: One of the 7 HealthPlanType values, exact text (V40). Info warning under the field (V41). | V8: v3 (changed) | W8: Changed: combo to strict dropdown; no learning of new values. Usage counts still feed the learned default. "No Plan/Issuer Response" only shows to provider initiators (always us). | X8: Yes
A9: 1 · Introduction & Qualification Questions | B9: 1.3 (6) | C9: qual | E9: 6 | F9: fehb_enrollment_code | G9: Enrollment Code: | H9: *Enrollment Code | J9: text | L9: Rule | N9: None | O9: No | P9: Yes | Q9: ^\d{3}$ | R9: must be 3 digits | T9: ^\d{3}$; shown and required only when q_plan_type = "Federal Employees Health Benefits (FEHB) carrier" (V42). | V9: v3 | W9: Required depends on other answers (portal rule in code) Guide: "the three digit *Enrollment Code". | X9: Yes
A10: 1 · Introduction & Qualification Questions | B10: 1.3 (9) | C10: qual | E10: 7 | F10: on_start_date | G10: When did the open negotiation period start? | H10: *When did the open negotiation period start? | J10: date | L10: Yes | N10: None | O10: No | P10: Yes | T10: YYYY-MM-DD; not in the future (V08). Timing bands: b < 31 = notice on Ready, blocks US desk filing (V43); 31–34 window helper (V14); b > 34 needs extension_reason (V13). | V10: v3 (changed) | W10: Batched with several ON dates: enter the ON start date of the first claim in the batch (guide note). b = business days from on_start_date to today, both days counted (the start date is day 1; federal holidays from the Holiday list). | X10: Yes
A11: 1 · Introduction & Qualification Questions | B11: 1.3 (9) | C11: qual | E11: 8 | F11: on_evidence | G11: Upload evidence of the open negotiation period start date (for example, the notice or notices of open negotiation sent to the non-initiating party). | H11: (upload) evidence of the open negotiation period start date | I11: At least one file. In a batch with different open negotiation start dates, enter the first claim’s date above and upload a notice for each start date. | J11: file | L11: Yes | N11: None | O11: No | P11: Yes | T11: At least 1 file (V24); one per distinct ON start date in a batch (reminder, V24). Dispute total <= 500 MB (V60). | V11: v4 (changed) | W11: Category on_evidence. Example: the notice(s) of open negotiation sent to the non-initiating party. Names seen: "OMB <account>.pdf", "PROOF <account>.png", "<date> LLC NSA NEG LETTER C <account>.pdf". v4: can be attached before the dispute or line is saved (staging). | X11: Yes
A12: 1 · Introduction & Qualification Questions | B12: 1.3 (9b, 9c) | C12: qual | E12: 9 | F12: extension_reason | G12: Extension justification reason: | H12: (extension justification reasons, shown when the date is more than 34 business days before today) | J12: radio | K12: ExtensionReason | L12: Rule | N12: None | O12: No | P12: Yes | T12: One of the 2 ExtensionReason texts (V13). | V12: v3 | W12: Required depends on other answers (portal rule in code) Without a reason, Ready is blocked ("Deadline passed"). | X12: Yes
A13: 1 · Introduction & Qualification Questions | B13: 1.3 (9c i) | C13: qual | E13: 10 | F13: ext_approval | G13: Upload a copy of the extension approval received from the Federal IDR Questions mailbox. | H13: (Upload) copy of the extension approval received from the Federal IDR Questions mailbox | J13: file | L13: Rule | N13: None | O13: No | P13: Yes | T13: At least 1 file (V44). | V13: v4 (changed) | W13: Required depends on other answers (portal rule in code) File category extension. v4: can be attached before the dispute or line is saved (staging). | X13: Yes
A14: 1 · Introduction & Qualification Questions | B14: 1.3 (9c ii) | C14: qual | E14: 11 | F14: cooling_dispute_ref | G14: Dispute Reference Number: | H14: Dispute Reference Number | J14: text | L14: Rule | N14: None | O14: No | P14: Yes | Q14: ^DISP-\d+$ | R14: is not valid: use the DISP-XXXXXX format | T14: ^DISP-\d+$ (V45). Portal: "Enter the dispute reference number." when empty. | V14: v3 | W14: Required depends on other answers (portal rule in code) The dispute number that triggered the cooling off period (portal format "DISP-XXXXXX"). | X14: Yes
A15: 1 · Introduction & Qualification Questions | B15: 1.3 (9c ii) | C15: qual | E15: 12 | F15: cooling_docs | G15: Upload a copy of the payment determination(s) that initiated the cooling off period (all of them if cooling off periods overlap). | H15: (Upload) copy of the payment determination(s) that initiated the cooling off period | J15: file | L15: Rule | N15: None | O15: No | P15: Yes | T15: At least 1 file (V46). | V15: v4 (changed) | W15: Required depends on other answers (portal rule in code) All determinations if cooling off periods overlap. File category cooling. v4: can be attached before the dispute or line is saved (staging). | X15: Yes
A16: 1 · Introduction & Qualification Questions | B16: 1.3 (10) | C16: qual | E16: 13 | F16: consent_waiver | G16: Did the health care provider or health care facility get consent from the participant, beneficiary, or enrollee to waive surprise billing protections for these items or services? | H16: *Did the health care provider or health care facility get consent from the participant, beneficiary, or enrollee to waive surprise billing protections for these items or services? | J16: radio | K16: YesNo | L16: Yes | M16: No | N16: Learned | O16: No | P16: Yes | T16: Yes or No. Yes = hard stop (V12). | V16: v3 (changed) | W16: Label text changed in guide v15 (air ambulance wording dropped). | X16: Yes
A17: 2 · Dispute Type | B17: 1.4 (1) | C17: dtype | E17: 1 | F17: dispute_type | G17: What are you disputing today? | H17: *What are you disputing today? | J17: radio | K17: DisputeType | L17: Yes | M17: A batched dispute | N17: Learned | O17: No | P17: Yes | T17: One of the 2 DisputeType values (V62). | V17: v3 | W17: Portal option texts: "A single dispute. I’m disputing either (a) one service code that represents one item or service, or (b) one service code that represents multiple items or services (a bundled payment arrangement)."; "A batched dispute. I’m disputing multiple items or services related to the treatment of a similar condition.". Default batched (most used, learned). | X17: Yes
A18: 2 · Dispute Type | B18: 1.4 (1a) | C18: dtype | E18: 2 | F18: bundled_payment | G18: Are you disputing a bundled payment arrangement (multiple items or services billed or reimbursed under one service code)? | H18: Are you disputing a bundled payment arrangement (multiple items or services billed or reimbursed under one service code)? | J18: radio | K18: BundledPayment | L18: Rule | N18: None | O18: No | P18: Yes | T18: Yes or No (V62). | V18: v3 | W18: Required depends on other answers (portal rule in code) Shown only when dispute_type = A single dispute. | X18: Yes
A19: 2 · Dispute Type | B19: 1.4 (1b) | C19: dtype | E19: 3 | F19: batch_qualifies | G19: I reviewed the batching questions and this dispute qualifies | H19: Do your disputes qualify for the batching process? (Studio: "I reviewed the batching questions and this dispute qualifies") | I19: The portal asks "Do your disputes qualify for the batching process?" in a pop-up. Answer Yes there only when this is ticked. | J19: check | L19: Rule | N19: None | O19: No | P19: Yes | T19: Checked (V62). | V19: v3 | W19: Required depends on other answers (portal rule in code) Mirrors the portal pop-up. On the portal: No returns to single dispute; Yes continues. | X19: Yes
A20: 3 · Contact Information – Initiating party | B20: 1.5.1 (1a) | C20: init | D20: Name and Address Information | E20: 1 | F20: prov_name | G20: Health care provider name: | H20: *Health care provider name | J20: combo | K20: BillingEntity | L20: Yes | N20: Learned | O20: No | P20: Yes | T20: Name characters (V58); typo check (V31). | V20: v3 (changed) | W20: Billing entity combo at the top of the page: picking it fills q_acting_as, tin, npi, prov_group_name and the contact fields below (L06). Also the signature name. Billing entity: suggestions and auto-fill come from the BillingEntities tab (v4). | X20: Yes
A21: 3 · Contact Information – Initiating party | B21: 1.5.1 (1b) | C21: init | D21: Name and Address Information | E21: 2 | F21: prov_group_name | G21: Hospital, Health Care Facility or Group Name: | H21: *Hospital, Health Care Facility or Group Name | J21: text | L21: Yes | N21: None | O21: No | P21: Yes | T21: Required (V01); name characters (V58). | U21: BillingEntity.group_name | V21: v3 (changed) | W21: Changed: optional in v2, REQUIRED in v3. Only Capital Health, PLLC has a group name today. | X21: Yes
A22: 3 · Contact Information – Initiating party | B22: 1.5.1 (1) | C22: init | D22: Name and Address Information | E22: 3 | F22: prov_email | G22: Email: | H22: *Email | J22: email | L22: Yes | N22: None | O22: No | P22: Yes | T22: V04 | U22: BillingEntity.email | V22: v2 | W22: Organization handling the dispute. | X22: Yes
A23: 3 · Contact Information – Initiating party | B23: 1.5.1 (1) | C23: init | D23: Name and Address Information | E23: 4 | F23: prov_phone | G23: Phone: | H23: *Phone | J23: phone | L23: Yes | N23: None | O23: No | P23: Yes | T23: V03 | U23: BillingEntity.phone | V23: v2 | X23: Yes
A24: 3 · Contact Information – Initiating party | B24: 1.5.1 (1) | C24: init | D24: Name and Address Information | E24: 5 | F24: prov_fax | G24: Fax: | H24: Fax | J24: phone | L24: No | N24: None | O24: No | P24: Yes | T24: V03 | U24: BillingEntity.fax | V24: v2 | X24: Yes
A25: 3 · Contact Information – Initiating party | B25: 1.5.1 (1) | C25: init | D25: Name and Address Information | E25: 6 | F25: prov_addr1 | G25: Mailing Address: | H25: *Mailing Address | J25: text | L25: Yes | N25: None | O25: No | P25: Yes | T25: Address characters (V59). | U25: BillingEntity.addr1 | V25: v2 | X25: Yes
A26: 3 · Contact Information – Initiating party | B26: 1.5.1 (1) | C26: init | D26: Name and Address Information | E26: 7 | F26: prov_addr2 | G26: Mailing Address Line 2: | H26: Mailing Address Line 2 (Studio; not in the guide v15 list) | J26: text | L26: No | N26: None | O26: No | P26: Yes | T26: Address characters (V59). | U26: BillingEntity.addr2 | V26: v2 | W26: Kept from v2 (Code.gs mainContact_). Guide v15 lists one address line (Open questions Q26). | X26: Yes
A27: 3 · Contact Information – Initiating party | B27: 1.5.1 (1) | C27: init | D27: Name and Address Information | E27: 8 | F27: prov_city | G27: City: | H27: *City | J27: text | L27: Yes | N27: None | O27: No | P27: Yes | T27: Address characters (V59). | U27: BillingEntity.city | V27: v2 | X27: Yes
A28: 3 · Contact Information – Initiating party | B28: 1.5.1 (1) | C28: init | D28: Name and Address Information | E28: 9 | F28: prov_state | G28: State: | H28: *State | J28: select | K28: State | L28: Yes | M28: TX | N28: Learned | O28: No | P28: Yes | T28: Strict select from State (V32). | U28: BillingEntity.state | V28: v3 (changed) | W28: Default TX (fixed business fact). | X28: Yes
A29: 3 · Contact Information – Initiating party | B29: 1.5.1 (1) | C29: init | D29: Name and Address Information | E29: 10 | F29: prov_zip | G29: ZIP Code: | H29: *ZIP Code | J29: zip | L29: Yes | N29: None | O29: No | P29: Yes | T29: V02 | U29: BillingEntity.zip | V29: v2 | X29: Yes
A30: 3 · Contact Information – Initiating party | B30: 1.5.1 (2) | C30: init | D30: Primary point of contact if different from above: | E30: 1 | F30: prov_p1_name | G30: Primary Contact Name: | H30: Primary Contact Name | J30: text | L30: No | N30: None | O30: No | P30: Yes | T30: Name characters (V58). Full contact incl. mailing address required once a name is entered (V64). | V30: v3 (changed) | W30: Collapsed by default ("Add point of contact"). Empty on all 4 notices. Studio order: name, email, phone, address (Code.gs pocSection_); the guide lists phone/email in a slightly different order per section. | X30: Yes
A31: 3 · Contact Information – Initiating party | B31: 1.5.1 (2) | C31: init | D31: Primary point of contact if different from above: | E31: 2 | F31: prov_p1_email | G31: Email: | H31: Email | J31: email | L31: Rule | N31: None | O31: No | P31: Yes | T31: V04 Full contact incl. mailing address required once a name is entered (V64). | V31: v2 | W31: Required depends on other answers (portal rule in code) | X31: Yes
A32: 3 · Contact Information – Initiating party | B32: 1.5.1 (2) | C32: init | D32: Primary point of contact if different from above: | E32: 3 | F32: prov_p1_phone | G32: Phone: | H32: Phone | J32: phone | L32: Rule | N32: None | O32: No | P32: Yes | T32: V03 Full contact incl. mailing address required once a name is entered (V64). | V32: v2 | W32: Required depends on other answers (portal rule in code) | X32: Yes
A33: 3 · Contact Information – Initiating party | B33: 1.5.1 (2) | C33: init | D33: Primary point of contact if different from above: | E33: 4 | F33: prov_p1_addr1 | G33: Mailing Address: | H33: Mailing Address | J33: text | L33: Rule | N33: None | O33: No | P33: Yes | T33: Full contact incl. mailing address required once a name is entered (V64). | V33: v2 | W33: Required depends on other answers (portal rule in code) | X33: Yes
A34: 3 · Contact Information – Initiating party | B34: 1.5.1 (2) | C34: init | D34: Primary point of contact if different from above: | E34: 5 | F34: prov_p1_addr2 | G34: Mailing Address Line 2: | H34: Mailing Address Line 2 (Studio) | J34: text | L34: No | N34: None | O34: No | P34: Yes | T34: Full contact incl. mailing address required once a name is entered (V64). | V34: v2 | X34: Yes
A35: 3 · Contact Information – Initiating party | B35: 1.5.1 (2) | C35: init | D35: Primary point of contact if different from above: | E35: 6 | F35: prov_p1_city | G35: City: | H35: City | J35: text | L35: Rule | N35: None | O35: No | P35: Yes | T35: Full contact incl. mailing address required once a name is entered (V64). | V35: v2 | W35: Required depends on other answers (portal rule in code) | X35: Yes
A36: 3 · Contact Information – Initiating party | B36: 1.5.1 (2) | C36: init | D36: Primary point of contact if different from above: | E36: 7 | F36: prov_p1_state | G36: State: | H36: State | J36: select | K36: State | L36: Rule | N36: None | O36: No | P36: Yes | T36: Strict select from State (V32). Full contact incl. mailing address required once a name is entered (V64). | V36: v2 | W36: Required depends on other answers (portal rule in code) | X36: Yes
A37: 3 · Contact Information – Initiating party | B37: 1.5.1 (2) | C37: init | D37: Primary point of contact if different from above: | E37: 8 | F37: prov_p1_zip | G37: ZIP Code: | H37: ZIP Code | J37: zip | L37: Rule | N37: None | O37: No | P37: Yes | T37: V02 Full contact incl. mailing address required once a name is entered (V64). | V37: v2 | W37: Required depends on other answers (portal rule in code) | X37: Yes
A38: 3 · Contact Information – Initiating party | B38: 1.5.1 (3) | C38: init | D38: Secondary point of contact: (optional) | E38: 1 | F38: prov_p2_name | G38: Secondary Contact Name: | H38: Secondary Contact Name | J38: text | L38: No | N38: None | O38: No | P38: Yes | T38: Name characters (V58). Full contact incl. mailing address required once a name is entered (V64). | V38: v3 (changed) | W38: Collapsed by default ("Add point of contact"). Empty on all 4 notices. Studio order: name, email, phone, address (Code.gs pocSection_); the guide lists phone/email in a slightly different order per section. | X38: Yes
A39: 3 · Contact Information – Initiating party | B39: 1.5.1 (3) | C39: init | D39: Secondary point of contact: (optional) | E39: 2 | F39: prov_p2_email | G39: Email: | H39: Email | J39: email | L39: Rule | N39: None | O39: No | P39: Yes | T39: V04 Full contact incl. mailing address required once a name is entered (V64). | V39: v2 | W39: Required depends on other answers (portal rule in code) | X39: Yes
A40: 3 · Contact Information – Initiating party | B40: 1.5.1 (3) | C40: init | D40: Secondary point of contact: (optional) | E40: 3 | F40: prov_p2_phone | G40: Phone: | H40: Phone | J40: phone | L40: Rule | N40: None | O40: No | P40: Yes | T40: V03 Full contact incl. mailing address required once a name is entered (V64). | V40: v2 | W40: Required depends on other answers (portal rule in code) | X40: Yes
...

Sheet Lists
A1: List | B1: Key | C1: Value | D1: Label | E1: Data JSON | F1: Count (seed) | G1: Source | H1: Status | I1: Sort | J1: Strict | K1: Flag / note
A2: State | C2: AL | F2: 0 | G2: seed | H2: Active
A3: State | C3: AK | F3: 0 | G3: seed | H3: Active
A4: State | C4: AZ | F4: 0 | G4: seed | H4: Active
A5: State | C5: AR | F5: 0 | G5: seed | H5: Active
A6: State | C6: CA | F6: 0 | G6: seed | H6: Active
A7: State | C7: CO | F7: 0 | G7: seed | H7: Active
A8: State | C8: CT | F8: 0 | G8: seed | H8: Active
A9: State | C9: DE | F9: 0 | G9: seed | H9: Active
A10: State | C10: DC | F10: 0 | G10: seed | H10: Active
A11: State | C11: FL | F11: 0 | G11: seed | H11: Active
A12: State | C12: GA | F12: 0 | G12: seed | H12: Active
A13: State | C13: HI | F13: 0 | G13: seed | H13: Active
... A57: State | C57: VI | F57: 0 | G57: seed | H57: Active
A58: YesNo | B58: yes | C58: Yes | F58: 0 | G58: seed | H58: Active | I58: 1 | J58: Yes | K58: Strict: portal wording, never learns. Rewording keeps the Key; the rules use the Key.
A59: YesNo | B59: no | C59: No | F59: 0 | G59: seed | H59: Active | I59: 2 | J59: Yes | K59: Strict: portal wording, never learns. Rewording keeps the Key; the rules use the Key.
A60: BundledPayment | B60: yes | C60: Yes | F60: 0 | G60: seed | H60: Active | I60: 1 | J60: Yes | K60: Strict: portal wording, never learns. Rewording keeps the Key; the rules use the Key.
A61: BundledPayment | B61: no | C61: No | F61: 0 | G61: seed | H61: Active | I61: 2 | J61: Yes | K61: Strict: portal wording, never learns. Rewording keeps the Key; the rules use the Key.
A62: ActingAs | B62: provider | C62: Health care provider | F62: 0 | G62: seed | H62: Active | I62: 1 | J62: Yes | K62: Strict: portal wording, never learns. Rewording keeps the Key; the rules use the Key.
A63: ActingAs | B63: facility | C63: Health care facility | F63: 0 | G63: seed | H63: Active | I63: 2 | J63: Yes | K63: Strict: portal wording, never learns. Rewording keeps the Key; the rules use the Key.
A64: PlanRole | B64: group | C64: Group health plan | F64: 0 | G64: seed | H64: Active | I64: 1 | J64: Yes | K64: Strict: portal wording, never learns. Rewording keeps the Key; the rules use the Key.
A65: PlanRole | B65: individual | C65: Individual health insurance issuer | F65: 0 | G65: seed | H65: Active | I65: 2 | J65: Yes | K65: Strict: portal wording, never learns. Rewording keeps the Key; the rules use the Key.
A66: PlanRole | B66: fehb | C66: Federal Employee Health Benefits (FEHB) carrier | F66: 0 | G66: seed | H66: Active | I66: 3 | J66: Yes | K66: Strict: portal wording, never learns. Rewording keeps the Key; the rules use the Key.
A67: HealthPlanType | B67: individual | C67: Individual health insurance issuer | F67: 0 | G67: seed | H67: Active | I67: 1 | J67: Yes | K67: Strict: portal wording, never learns. Rewording keeps the Key; the rules use the Key.
A68: HealthPlanType | B68: fully_insured | C68: Fully-insured ERISA group health plan | F68: 0 | G68: seed | H68: Active | I68: 2 | J68: Yes | K68: Strict: portal wording, never learns. Rewording keeps the Key; the rules use the Key.
A69: HealthPlanType | B69: fehb | C69: Federal Employees Health Benefits (FEHB) carrier | F69: 0 | G69: seed | H69: Active | I69: 3 | J69: Yes | K69: Strict: portal wording, never learns. Rewording keeps the Key; the rules use the Key.
... A73: HealthPlanType | B73: no_response | C73: No Plan/Issuer Response | F73: 0 | G73: seed | H73: Active | I73: 7 | J73: Yes | K73: Strict: portal wording, never learns. Rewording keeps the Key; the rules use the Key.
A74: DisputeType | B74: single | C74: A single dispute | D74: I’m disputing either (a) one service code that represents one item or service, or (b) one service code that represents multiple items or services (a bundled payment arrangement). | F74: 0 | G74: seed | H74: Active | I74: 1 | J74: Yes | K74: Strict: portal wording, never learns. Rewording keeps the Key; the rules use the Key.
A75: DisputeType | B75: batched | C75: A batched dispute | D75: I’m disputing multiple items or services related to the treatment of a similar condition. | F75: 0 | G75: seed | H75: Active | I75: 2 | J75: Yes | K75: Strict: portal wording, never learns. Rewording keeps the Key; the rules use the Key.
A76: ExtensionReason | B76: approval | C76: I received an extension approval from the Federal IDR mailbox and will upload evidence of this extension in the Supporting Documentation section of this web form. | D76: Extension approval | F76: 0 | G76: seed | H76: Active | I76: 1 | J76: Yes | K76: Strict: portal wording, never learns. Rewording keeps the Key; the rules use the Key.
A77: ExtensionReason | B77: cooling | C77: The item(s) or service(s) under dispute was subject to the cooling off period. | D77: Cooling off period | F77: 0 | G77: seed | H77: Active | I77: 2 | J77: Yes | K77: Strict: portal wording, never learns. Rewording keeps the Key; the rules use the Key.
A78: ItemType | B78: emergency | C78: Emergency item(s)/service(s) | F78: 0 | G78: seed | H78: Active | I78: 1 | J78: Yes | K78: Strict: portal wording, never learns. Rewording keeps the Key; the rules use the Key.
A79: ItemType | B79: post_stabilization | C79: Post-stabilization service(s) | F79: 0 | G79: seed | H79: Active | I79: 2 | J79: Yes | K79: Strict: portal wording, never learns. Rewording keeps the Key; the rules use the Key.
A80: ItemType | B80: professional | C80: Professional service(s) | F80: 0 | G80: seed | H80: Active | I80: 3 | J80: Yes | K80: Strict: portal wording, never learns. Rewording keeps the Key; the rules use the Key.
A81: ItemType | B81: hospital_based | C81: Hospital-based service(s) | F81: 0 | G81: seed | H81: Active | I81: 4 | J81: Yes | K81: Strict: portal wording, never learns. Rewording keeps the Key; the rules use the Key.
A82: ItemType | B82: nonpar_at_par | C82: Item(s)/service(s) furnished by a nonparticipating provider at a participating health care facility | F82: 0 | G82: seed | H82: Active | I82: 5 | J82: Yes | K82: Strict: portal wording, never learns. Rewording keeps the Key; the rules use the Key.
A83: ItemType | B83: other | C83: Other: Provide description | F83: 0 | G83: seed | H83: Active | I83: 6 | J83: Yes | K83: Strict: portal wording, never learns. Rewording keeps the Key; the rules use the Key.
A84: LineType | B84: bundled | C84: Bundled Item or Service | F84: 0 | G84: seed | H84: Active | I84: 1 | J84: Yes | K84: Strict: portal wording, never learns. Rewording keeps the Key; the rules use the Key.
A85: LineType | B85: component | C85: Component Item or Service | F85: 0 | G85: seed | H85: Active | I85: 2 | J85: Yes | K85: Strict: portal wording, never learns. Rewording keeps the Key; the rules use the Key.
A86: NipMethod | B86: email | C86: Email | F86: 0 | G86: seed | H86: Active | I86: 1 | J86: Yes | K86: Strict: portal wording, never learns. Rewording keeps the Key; the rules use the Key.
...

Sheet Payers
A1: Name (non-initiating party) | B1: Mailing Address | C1: City | D1: State | E1: ZIP Code | F1: Email | G1: Phone | H1: Fax | I1: Aliases | J1: Times seen (4 notices) | K1: Seen on dispute | L1: Portal name check | M1: Flag / note
A2: 90 Degree Benefits | J2: 0 | L2: OK | M2: Contact details needed.
A3: ABA | J3: 0 | L3: OK | M3: Contact details needed.
A4: Aetna | J4: 0 | L4: OK | M4: Contact details needed.
A5: Allegiance | J5: 0 | L5: OK | M5: Contact details needed.
A6: Allegiance Benefi Plan Management, Inc | J6: 0 | L6: OK | M6: Contact details needed. Possible typo "Benefi"; also close to "Allegiance". Business to confirm.
A7: Allied Benefit Systems, Inc. | J7: 0 | L7: OK | M7: Contact details needed.
A8: Allstate | J8: 0 | L8: OK | M8: Contact details needed.
A9: Ambetter-Superior HealthPlan | J9: 0 | L9: OK | M9: Contact details needed.
A10: Angle Health | J10: 0 | L10: OK | M10: Contact details needed.
A11: Ameriben | J11: 0 | L11: OK | M11: Contact details needed.
A12: APWU Health Plan | J12: 0 | L12: OK | M12: Contact details needed.
A13: Assured Benefits Administrator | J13: 0 | L13: OK | M13: Contact details needed.
... A16: Baylor Scott & White | J16: 0 | L16: OK | M16: Contact details needed.
A17: BCBS | B17: PO BOX 660044 | C17: Dallas | D17: TX | E17: 75266 | F17: nsa.disputes@bcbstx.com | G17: (800) 451-0287 | I17: BLUECROSS BLUESHIELD | J17: 1 | K17: DISP-7998956 | L17: OK
A18: Benefit & Risk Management Services- BRMS | J18: 0 | L18: OK | M18: Contact details needed.
A19: BENEFITS HEALTHSMART | J19: 0 | L19: OK | M19: Contact details needed. Kept separate from Healthsmart (may be a different TPA). Business to confirm.
A20: Boon Chapman | J20: 0 | L20: OK | M20: Contact details needed.
A21: Bright HealthCare | J21: 0 | L21: OK | M21: Contact details needed.
A22: Cantex Inc | J22: 0 | L22: OK | M22: Contact details needed.
A23: CareFactor | J23: 0 | L23: OK | M23: Contact details needed.
A24: Centivo | J24: 0 | L24: OK | M24: Contact details needed.
A25: CGS Health | J25: 0 | L25: OK | M25: Contact details needed.
A26: Chesterfield Resources Inc. | J26: 0 | L26: OK | M26: Contact details needed.
A27: Cigna | B27: P.O. BOX 182223 | C27: CHATTANOOGA | D27: TN | E27: 37422-7223 | F27: nsaidr@multiplan.com | G27: (800) 244-6224 | J27: 1 | K27: DISP-7997846 | L27: OK
A28: CITY OF FORT WORTH | J28: 0 | L28: OK | M28: Contact details needed.
A29: Coeur Plan | J29: 0 | L29: OK | M29: Contact details needed.
A30: Concord Hospital Entreprises | J30: 0 | L30: OK | M30: Contact details needed. Possible typo "Entreprises". Business to confirm.
A31: Connected Care | J31: 0 | L31: OK | M31: Contact details needed.
A32: COOK CHILDREN'S HEALTH CARE SYSTEM | J32: 0 | L32: OK | M32: Contact details needed.
A33: Dean Health Plan | J33: 0 | L33: OK | M33: Contact details needed.
A34: EMI Health | J34: 0 | L34: OK | M34: Contact details needed.
A35: Employers Health Network | J35: 0 | L35: OK | M35: Contact details needed.
A36: Enterprise Group Planning, INC | J36: 0 | L36: OK | M36: Contact details needed.
A37: EVHC | J37: 0 | L37: OK | M37: Contact details needed.
A38: First Health Network | J38: 0 | L38: OK | M38: Contact details needed.
A39: Fringe Benefit Group | J39: 0 | L39: OK | M39: Contact details needed.
... A54: healthnet | J54: 0 | L54: OK | M54: Contact details needed. All lower case. Business to confirm the display name.
A55: HealthNow | I55: Health Now | J55: 0 | L55: OK | M55: Contact details needed.
A56: HealthScope Benefits | J56: 0 | L56: OK | M56: Contact details needed.
...

Sheet BillingEntities
A1: Name | B1: ActingAs | C1: TIN | D1: NPI | E1: GroupName | F1: Addr1 | G1: Addr2 | H1: City | I1: State | J1: ZIP | K1: Email | L1: Phone | M1: Fax | N1: Confirmed | O1: Status | P1: Count | Q1: LastUsed | R1: AddedBy | S1: AddedAt | T1: Notes | U1: Aliases | V1: Flag / note
A2: Jade Medical, PLLC | B2: Health care provider | N2: No | O2: Active | P2: 0 | R2: setup | S2: (setup time) | V2: ActingAs is a guess from the legal suffix (PLLC -> provider, LLC -> facility); Confirmed No until a saved dispute confirms it. TIN, NPI, GroupName and contact needed (learned on first save or entered in Admin -> Billing entities).
A3: Deerfield plains, LLC | B3: Health care facility | N3: No | O3: Active | P3: 0 | R3: setup | S3: (setup time) | V3: ActingAs is a guess from the legal suffix (PLLC -> provider, LLC -> facility); Confirmed No until a saved dispute confirms it. TIN, NPI, GroupName and contact needed (learned on first save or entered in Admin -> Billing entities). Possible typo to confirm (not changed): Lower-case "plains" (Deerfield Plains?).
A4: CareMed, PLLC | B4: Health care provider | N4: No | O4: Active | P4: 0 | R4: setup | S4: (setup time) | V4: ActingAs is a guess from the legal suffix (PLLC -> provider, LLC -> facility); Confirmed No until a saved dispute confirms it. TIN, NPI, GroupName and contact needed (learned on first save or entered in Admin -> Billing entities).
A5: Sycamore Rush, LLC | B5: Health care facility | N5: No | O5: Active | P5: 0 | R5: setup | S5: (setup time) | V5: ActingAs is a guess from the legal suffix (PLLC -> provider, LLC -> facility); Confirmed No until a saved dispute confirms it. TIN, NPI, GroupName and contact needed (learned on first save or entered in Admin -> Billing entities).
A6: WRFER University, LLC | B6: Health care facility | N6: No | O6: Active | P6: 0 | R6: setup | S6: (setup time) | V6: ActingAs is a guess from the legal suffix (PLLC -> provider, LLC -> facility); Confirmed No until a saved dispute confirms it. TIN, NPI, GroupName and contact needed (learned on first save or entered in Admin -> Billing entities). Possible typo to confirm (not changed): "WRFER" vs "WFRER" in WFRER Denton and WFRER Cooper.
A7: Windview First, PLLC | B7: Health care provider | N7: No | O7: Active | P7: 0 | R7: setup | S7: (setup time) | V7: ActingAs is a guess from the legal suffix (PLLC -> provider, LLC -> facility); Confirmed No until a saved dispute confirms it. TIN, NPI, GroupName and contact needed (learned on first save or entered in Admin -> Billing entities).
A8: Capital Health, PLLC | B8: Health care provider | C8: 872524265 | D8: 1609548056 | E8: Totalcare ER, Cedar Hill | F8: 6049 S. Hulen St. | H8: Fort Worth | I8: TX | J8: 76132 | K8: cedarhill.negotiations@totalcare.us | L8: (817) 566-1232 | N8: Yes | O8: Active | P8: 1 | R8: setup | S8: (setup time) | U8: CAPITAL HEALTH PLLC | V8: ActingAs confirmed by the 4 notices. v2 spellings kept in Aliases.
A9: Silver Alliance, LLC | B9: Health care facility | C9: 862923814 | D9: 1972273233 | F9: 6049 S. Hulen St. | H9: Fort Worth | I9: TX | J9: 76132 | K9: cedarhill.negotiations@totalcare.us | L9: (817) 566-1232 | N9: Yes | O9: Active | P9: 3 | R9: setup | S9: (setup time) | U9: SILVER ALLIANCE LLC; SILVER ALLIANCE,LLC | V9: ActingAs confirmed by the 4 notices. v2 spellings kept in Aliases. GroupName missing; now required on page 3.
A10: Trans Oakley, LLC | B10: Health care facility | N10: No | O10: Active | P10: 0 | R10: setup | S10: (setup time) | V10: ActingAs is a guess from the legal suffix (PLLC -> provider, LLC -> facility); Confirmed No until a saved dispute confirms it. TIN, NPI, GroupName and contact needed (learned on first save or entered in Admin -> Billing entities).
A11: Eastern Elm, PLLC | B11: Health care provider | N11: No | O11: Active | P11: 0 | R11: setup | S11: (setup time) | V11: ActingAs is a guess from the legal suffix (PLLC -> provider, LLC -> facility); Confirmed No until a saved dispute confirms it. TIN, NPI, GroupName and contact needed (learned on first save or entered in Admin -> Billing entities).
A12: Lakewood Green, LLC | B12: Health care facility | N12: No | O12: Active | P12: 0 | R12: setup | S12: (setup time) | V12: ActingAs is a guess from the legal suffix (PLLC -> provider, LLC -> facility); Confirmed No until a saved dispute confirms it. TIN, NPI, GroupName and contact needed (learned on first save or entered in Admin -> Billing entities).
A13: Silver choice, PLLC | B13: Health care provider | N13: No | O13: Active | P13: 0 | R13: setup | S13: (setup time) | V13: ActingAs is a guess from the legal suffix (PLLC -> provider, LLC -> facility); Confirmed No until a saved dispute confirms it. TIN, NPI, GroupName and contact needed (learned on first save or entered in Admin -> Billing entities). Possible typo to confirm (not changed): Lower-case "choice" (Silver Choice?).
A14: Greenwood South, LLC | B14: Health care facility | N14: No | O14: Active | P14: 0 | R14: setup | S14: (setup time) | V14: ActingAs is a guess from the legal suffix (PLLC -> provider, LLC -> facility); Confirmed No until a saved dispute confirms it. TIN, NPI, GroupName and contact needed (learned on first save or entered in Admin -> Billing entities).
A15: Aspen Willow, PLLC | B15: Health care provider | N15: No | O15: Active | P15: 0 | R15: setup | S15: (setup time) | V15: ActingAs is a guess from the legal suffix (PLLC -> provider, LLC -> facility); Confirmed No until a saved dispute confirms it. TIN, NPI, GroupName and contact needed (learned on first save or entered in Admin -> Billing entities).
A16: RSER Benbrook, LLC | B16: Health care facility | N16: No | O16: Active | P16: 0 | R16: setup | S16: (setup time) | V16: ActingAs is a guess from the legal suffix (PLLC -> provider, LLC -> facility); Confirmed No until a saved dispute confirms it. TIN, NPI, GroupName and contact needed (learned on first save or entered in Admin -> Billing entities). Possible typo to confirm (not changed): "RSER" (compare TotalCare ER Benbrook, PLLC).
A17: TotalCare ER Benbrook, PLLC | B17: Health care provider | N17: No | O17: Active | P17: 0 | R17: setup | S17: (setup time) | V17: ActingAs is a guess from the legal suffix (PLLC -> provider, LLC -> facility); Confirmed No until a saved dispute confirms it. TIN, NPI, GroupName and contact needed (learned on first save or entered in Admin -> Billing entities).
A18: Cedar Physcians, PLLC | B18: Health care provider | N18: No | O18: Active | P18: 0 | R18: setup | S18: (setup time) | V18: ActingAs is a guess from the legal suffix (PLLC -> provider, LLC -> facility); Confirmed No until a saved dispute confirms it. TIN, NPI, GroupName and contact needed (learned on first save or entered in Admin -> Billing entities). Possible typo to confirm (not changed): "Physcians" (Physicians?).
A19: WFRER Denton, LLC | B19: Health care facility | N19: No | O19: Active | P19: 0 | R19: setup | S19: (setup time) | V19: ActingAs is a guess from the legal suffix (PLLC -> provider, LLC -> facility); Confirmed No until a saved dispute confirms it. TIN, NPI, GroupName and contact needed (learned on first save or entered in Admin -> Billing entities).
A20: Sun Choice, PLLC | B20: Health care provider | N20: No | O20: Active | P20: 0 | R20: setup | S20: (setup time) | V20: ActingAs is a guess from the legal suffix (PLLC -> provider, LLC -> facility); Confirmed No until a saved dispute confirms it. TIN, NPI, GroupName and contact needed (learned on first save or entered in Admin -> Billing entities).
A21: WFRER Cooper, LLC | B21: Health care facility | N21: No | O21: Active | P21: 0 | R21: setup | S21: (setup time) | V21: ActingAs is a guess from the legal suffix (PLLC -> provider, LLC -> facility); Confirmed No until a saved dispute confirms it. TIN, NPI, GroupName and contact needed (learned on first save or entered in Admin -> Billing entities).
... A25: Gracious Health, LLC | B25: Health care facility | N25: No | O25: Active | P25: 0 | R25: setup | S25: (setup time) | V25: ActingAs is a guess from the legal suffix (PLLC -> provider, LLC -> facility); Confirmed No until a saved dispute confirms it. TIN, NPI, GroupName and contact needed (learned on first save or entered in Admin -> Billing entities).
A27: Note | B27: Seed rows of the BillingEntities tab exactly as setup() writes them (Code.gs seedEntityRows_). setup() moves v3 BillingEntity rows from Options here (Data JSON -> columns, alias rows -> Aliases). Legal names exactly as given; not corrected.

Sheet ServiceCodes
A1: Code | B1: Description (label) | C1: Times seen | D1: Lines with a QPA | E1: QPA min | F1: QPA max | G1: Typical QPA range seen | H1: Source | I1: Format check (5 alphanumeric)
A2: 99285 | C2: =COUNTIF('Observed lines'!$F$2:$F$36,A2) -> 0 | D2: =COUNTIFS('Observed lines'!$F$2:$F$36,A2,'Observed lines'!$G$2:$G$36,"<>") -> 0 | E2: =IF(D2=0,"",_xlfn.MINIFS('Observed lines'!$G$2:$G$36,'Observed lines'!$F$2:$F$36,A2)) | F2: =IF(D2=0,"",_xlfn.MAXIFS('Observed lines'!$G$2:$G$36,'Observed lines'!$F$2:$F$36,A2)) | G2: =IF(D2=0,"none seen",IF(E2=F2,TEXT(E2,"$#,##0.00"),TEXT(E2,"$#,##0.00")&" – "&TEXT(F2,"$#,##0.00"))) -> none seen | H2: seed (business list) | I2: OK
A3: 99284 | B3: EMERGENCY ROOM SERVICE | C3: =COUNTIF('Observed lines'!$F$2:$F$36,A3) -> 3 | D3: =COUNTIFS('Observed lines'!$F$2:$F$36,A3,'Observed lines'!$G$2:$G$36,"<>") -> 2 | E3: =IF(D3=0,"",_xlfn.MINIFS('Observed lines'!$G$2:$G$36,'Observed lines'!$F$2:$F$36,A3)) -> 250.3 | F3: =IF(D3=0,"",_xlfn.MAXIFS('Observed lines'!$G$2:$G$36,'Observed lines'!$F$2:$F$36,A3)) -> 1052.46 | G3: =IF(D3=0,"none seen",IF(E3=F3,TEXT(E3,"$#,##0.00"),TEXT(E3,"$#,##0.00")&" – "&TEXT(F3,"$#,##0.00"))) -> $250.30 – $1,052.46 | H3: seed + observed | I3: OK
A4: 99291 | C4: =COUNTIF('Observed lines'!$F$2:$F$36,A4) -> 0 | D4: =COUNTIFS('Observed lines'!$F$2:$F$36,A4,'Observed lines'!$G$2:$G$36,"<>") -> 0 | E4: =IF(D4=0,"",_xlfn.MINIFS('Observed lines'!$G$2:$G$36,'Observed lines'!$F$2:$F$36,A4)) | F4: =IF(D4=0,"",_xlfn.MAXIFS('Observed lines'!$G$2:$G$36,'Observed lines'!$F$2:$F$36,A4)) | G4: =IF(D4=0,"none seen",IF(E4=F4,TEXT(E4,"$#,##0.00"),TEXT(E4,"$#,##0.00")&" – "&TEXT(F4,"$#,##0.00"))) -> none seen | H4: seed (business list) | I4: OK
A5: 70450 | B5: CT HEAD/BRAIN W/O DYE | C5: =COUNTIF('Observed lines'!$F$2:$F$36,A5) -> 1 | D5: =COUNTIFS('Observed lines'!$F$2:$F$36,A5,'Observed lines'!$G$2:$G$36,"<>") -> 1 | E5: =IF(D5=0,"",_xlfn.MINIFS('Observed lines'!$G$2:$G$36,'Observed lines'!$F$2:$F$36,A5)) -> 348.35 | F5: =IF(D5=0,"",_xlfn.MAXIFS('Observed lines'!$G$2:$G$36,'Observed lines'!$F$2:$F$36,A5)) -> 348.35 | G5: =IF(D5=0,"none seen",IF(E5=F5,TEXT(E5,"$#,##0.00"),TEXT(E5,"$#,##0.00")&" – "&TEXT(F5,"$#,##0.00"))) -> $348.35 | H5: seed + observed | I5: OK
A6: 74176 | C6: =COUNTIF('Observed lines'!$F$2:$F$36,A6) -> 0 | D6: =COUNTIFS('Observed lines'!$F$2:$F$36,A6,'Observed lines'!$G$2:$G$36,"<>") -> 0 | E6: =IF(D6=0,"",_xlfn.MINIFS('Observed lines'!$G$2:$G$36,'Observed lines'!$F$2:$F$36,A6)) | F6: =IF(D6=0,"",_xlfn.MAXIFS('Observed lines'!$G$2:$G$36,'Observed lines'!$F$2:$F$36,A6)) | G6: =IF(D6=0,"none seen",IF(E6=F6,TEXT(E6,"$#,##0.00"),TEXT(E6,"$#,##0.00")&" – "&TEXT(F6,"$#,##0.00"))) -> none seen | H6: seed (business list) | I6: OK
A7: 0202U | C7: =COUNTIF('Observed lines'!$F$2:$F$36,A7) -> 0 | D7: =COUNTIFS('Observed lines'!$F$2:$F$36,A7,'Observed lines'!$G$2:$G$36,"<>") -> 0 | E7: =IF(D7=0,"",_xlfn.MINIFS('Observed lines'!$G$2:$G$36,'Observed lines'!$F$2:$F$36,A7)) | F7: =IF(D7=0,"",_xlfn.MAXIFS('Observed lines'!$G$2:$G$36,'Observed lines'!$F$2:$F$36,A7)) | G7: =IF(D7=0,"none seen",IF(E7=F7,TEXT(E7,"$#,##0.00"),TEXT(E7,"$#,##0.00")&" – "&TEXT(F7,"$#,##0.00"))) -> none seen | H7: seed (business list) | I7: OK
A8: 71046 | C8: =COUNTIF('Observed lines'!$F$2:$F$36,A8) -> 0 | D8: =COUNTIFS('Observed lines'!$F$2:$F$36,A8,'Observed lines'!$G$2:$G$36,"<>") -> 0 | E8: =IF(D8=0,"",_xlfn.MINIFS('Observed lines'!$G$2:$G$36,'Observed lines'!$F$2:$F$36,A8)) | F8: =IF(D8=0,"",_xlfn.MAXIFS('Observed lines'!$G$2:$G$36,'Observed lines'!$F$2:$F$36,A8)) | G8: =IF(D8=0,"none seen",IF(E8=F8,TEXT(E8,"$#,##0.00"),TEXT(E8,"$#,##0.00")&" – "&TEXT(F8,"$#,##0.00"))) -> none seen | H8: seed (business list) | I8: OK
A9: 71100 | C9: =COUNTIF('Observed lines'!$F$2:$F$36,A9) -> 0 | D9: =COUNTIFS('Observed lines'!$F$2:$F$36,A9,'Observed lines'!$G$2:$G$36,"<>") -> 0 | E9: =IF(D9=0,"",_xlfn.MINIFS('Observed lines'!$G$2:$G$36,'Observed lines'!$F$2:$F$36,A9)) | F9: =IF(D9=0,"",_xlfn.MAXIFS('Observed lines'!$G$2:$G$36,'Observed lines'!$F$2:$F$36,A9)) | G9: =IF(D9=0,"none seen",IF(E9=F9,TEXT(E9,"$#,##0.00"),TEXT(E9,"$#,##0.00")&" – "&TEXT(F9,"$#,##0.00"))) -> none seen | H9: seed (business list) | I9: OK
A10: 99283 | B10: EMERGENCY ROOM SERVICE | C10: =COUNTIF('Observed lines'!$F$2:$F$36,A10) -> 1 | D10: =COUNTIFS('Observed lines'!$F$2:$F$36,A10,'Observed lines'!$G$2:$G$36,"<>") -> 1 | E10: =IF(D10=0,"",_xlfn.MINIFS('Observed lines'!$G$2:$G$36,'Observed lines'!$F$2:$F$36,A10)) -> 905.44 | F10: =IF(D10=0,"",_xlfn.MAXIFS('Observed lines'!$G$2:$G$36,'Observed lines'!$F$2:$F$36,A10)) -> 905.44 | G10: =IF(D10=0,"none seen",IF(E10=F10,TEXT(E10,"$#,##0.00"),TEXT(E10,"$#,##0.00")&" – "&TEXT(F10,"$#,##0.00"))) -> $905.44 | H10: seed + observed | I10: OK
A11: 27780 | C11: =COUNTIF('Observed lines'!$F$2:$F$36,A11) -> 0 | D11: =COUNTIFS('Observed lines'!$F$2:$F$36,A11,'Observed lines'!$G$2:$G$36,"<>") -> 0 | E11: =IF(D11=0,"",_xlfn.MINIFS('Observed lines'!$G$2:$G$36,'Observed lines'!$F$2:$F$36,A11)) | F11: =IF(D11=0,"",_xlfn.MAXIFS('Observed lines'!$G$2:$G$36,'Observed lines'!$F$2:$F$36,A11)) | G11: =IF(D11=0,"none seen",IF(E11=F11,TEXT(E11,"$#,##0.00"),TEXT(E11,"$#,##0.00")&" – "&TEXT(F11,"$#,##0.00"))) -> none seen | H11: seed (business list) | I11: OK
A12: 99000 | C12: =COUNTIF('Observed lines'!$F$2:$F$36,A12) -> 0 | D12: =COUNTIFS('Observed lines'!$F$2:$F$36,A12,'Observed lines'!$G$2:$G$36,"<>") -> 0 | E12: =IF(D12=0,"",_xlfn.MINIFS('Observed lines'!$G$2:$G$36,'Observed lines'!$F$2:$F$36,A12)) | F12: =IF(D12=0,"",_xlfn.MAXIFS('Observed lines'!$G$2:$G$36,'Observed lines'!$F$2:$F$36,A12)) | G12: =IF(D12=0,"none seen",IF(E12=F12,TEXT(E12,"$#,##0.00"),TEXT(E12,"$#,##0.00")&" – "&TEXT(F12,"$#,##0.00"))) -> none seen | H12: seed (business list) | I12: OK
A13: 36410 | C13: =COUNTIF('Observed lines'!$F$2:$F$36,A13) -> 0 | D13: =COUNTIFS('Observed lines'!$F$2:$F$36,A13,'Observed lines'!$G$2:$G$36,"<>") -> 0 | E13: =IF(D13=0,"",_xlfn.MINIFS('Observed lines'!$G$2:$G$36,'Observed lines'!$F$2:$F$36,A13)) | F13: =IF(D13=0,"",_xlfn.MAXIFS('Observed lines'!$G$2:$G$36,'Observed lines'!$F$2:$F$36,A13)) | G13: =IF(D13=0,"none seen",IF(E13=F13,TEXT(E13,"$#,##0.00"),TEXT(E13,"$#,##0.00")&" – "&TEXT(F13,"$#,##0.00"))) -> none seen | H13: seed (business list) | I13: OK
A14: 76705 | C14: =COUNTIF('Observed lines'!$F$2:$F$36,A14) -> 0 | D14: =COUNTIFS('Observed lines'!$F$2:$F$36,A14,'Observed lines'!$G$2:$G$36,"<>") -> 0 | E14: =IF(D14=0,"",_xlfn.MINIFS('Observed lines'!$G$2:$G$36,'Observed lines'!$F$2:$F$36,A14)) | F14: =IF(D14=0,"",_xlfn.MAXIFS('Observed lines'!$G$2:$G$36,'Observed lines'!$F$2:$F$36,A14)) | G14: =IF(D14=0,"none seen",IF(E14=F14,TEXT(E14,"$#,##0.00"),TEXT(E14,"$#,##0.00")&" – "&TEXT(F14,"$#,##0.00"))) -> none seen | H14: seed (business list) | I14: OK
A15: 96372 | B15: THERAPY/PROPHYLAXIS/DIAGNOSIS INJECTION, SC/IM | C15: =COUNTIF('Observed lines'!$F$2:$F$36,A15) -> 1 | D15: =COUNTIFS('Observed lines'!$F$2:$F$36,A15,'Observed lines'!$G$2:$G$36,"<>") -> 1 | E15: =IF(D15=0,"",_xlfn.MINIFS('Observed lines'!$G$2:$G$36,'Observed lines'!$F$2:$F$36,A15)) -> 37.78 | F15: =IF(D15=0,"",_xlfn.MAXIFS('Observed lines'!$G$2:$G$36,'Observed lines'!$F$2:$F$36,A15)) -> 37.78 | G15: =IF(D15=0,"none seen",IF(E15=F15,TEXT(E15,"$#,##0.00"),TEXT(E15,"$#,##0.00")&" – "&TEXT(F15,"$#,##0.00"))) -> $37.78 | H15: seed + observed | I15: OK
A16: 74177 | C16: =COUNTIF('Observed lines'!$F$2:$F$36,A16) -> 0 | D16: =COUNTIFS('Observed lines'!$F$2:$F$36,A16,'Observed lines'!$G$2:$G$36,"<>") -> 0 | E16: =IF(D16=0,"",_xlfn.MINIFS('Observed lines'!$G$2:$G$36,'Observed lines'!$F$2:$F$36,A16)) | F16: =IF(D16=0,"",_xlfn.MAXIFS('Observed lines'!$G$2:$G$36,'Observed lines'!$F$2:$F$36,A16)) | G16: =IF(D16=0,"none seen",IF(E16=F16,TEXT(E16,"$#,##0.00"),TEXT(E16,"$#,##0.00")&" – "&TEXT(F16,"$#,##0.00"))) -> none seen | H16: seed (business list) | I16: OK
A17: 96365 | C17: =COUNTIF('Observed lines'!$F$2:$F$36,A17) -> 0 | D17: =COUNTIFS('Observed lines'!$F$2:$F$36,A17,'Observed lines'!$G$2:$G$36,"<>") -> 0 | E17: =IF(D17=0,"",_xlfn.MINIFS('Observed lines'!$G$2:$G$36,'Observed lines'!$F$2:$F$36,A17)) | F17: =IF(D17=0,"",_xlfn.MAXIFS('Observed lines'!$G$2:$G$36,'Observed lines'!$F$2:$F$36,A17)) | G17: =IF(D17=0,"none seen",IF(E17=F17,TEXT(E17,"$#,##0.00"),TEXT(E17,"$#,##0.00")&" – "&TEXT(F17,"$#,##0.00"))) -> none seen | H17: seed (business list) | I17: OK
A18: 96366 | C18: =COUNTIF('Observed lines'!$F$2:$F$36,A18) -> 0 | D18: =COUNTIFS('Observed lines'!$F$2:$F$36,A18,'Observed lines'!$G$2:$G$36,"<>") -> 0 | E18: =IF(D18=0,"",_xlfn.MINIFS('Observed lines'!$G$2:$G$36,'Observed lines'!$F$2:$F$36,A18)) | F18: =IF(D18=0,"",_xlfn.MAXIFS('Observed lines'!$G$2:$G$36,'Observed lines'!$F$2:$F$36,A18)) | G18: =IF(D18=0,"none seen",IF(E18=F18,TEXT(E18,"$#,##0.00"),TEXT(E18,"$#,##0.00")&" – "&TEXT(F18,"$#,##0.00"))) -> none seen | H18: seed (business list) | I18: OK
A19: 96368 | C19: =COUNTIF('Observed lines'!$F$2:$F$36,A19) -> 0 | D19: =COUNTIFS('Observed lines'!$F$2:$F$36,A19,'Observed lines'!$G$2:$G$36,"<>") -> 0 | E19: =IF(D19=0,"",_xlfn.MINIFS('Observed lines'!$G$2:$G$36,'Observed lines'!$F$2:$F$36,A19)) | F19: =IF(D19=0,"",_xlfn.MAXIFS('Observed lines'!$G$2:$G$36,'Observed lines'!$F$2:$F$36,A19)) | G19: =IF(D19=0,"none seen",IF(E19=F19,TEXT(E19,"$#,##0.00"),TEXT(E19,"$#,##0.00")&" – "&TEXT(F19,"$#,##0.00"))) -> none seen | H19: seed (business list) | I19: OK
A20: 96375 | C20: =COUNTIF('Observed lines'!$F$2:$F$36,A20) -> 0 | D20: =COUNTIFS('Observed lines'!$F$2:$F$36,A20,'Observed lines'!$G$2:$G$36,"<>") -> 0 | E20: =IF(D20=0,"",_xlfn.MINIFS('Observed lines'!$G$2:$G$36,'Observed lines'!$F$2:$F$36,A20)) | F20: =IF(D20=0,"",_xlfn.MAXIFS('Observed lines'!$G$2:$G$36,'Observed lines'!$F$2:$F$36,A20)) | G20: =IF(D20=0,"none seen",IF(E20=F20,TEXT(E20,"$#,##0.00"),TEXT(E20,"$#,##0.00")&" – "&TEXT(F20,"$#,##0.00"))) -> none seen | H20: seed (business list) | I20: OK
A21: 72125 | B21: CT NECK SPINE W/O DYE | C21: =COUNTIF('Observed lines'!$F$2:$F$36,A21) -> 1 | D21: =COUNTIFS('Observed lines'!$F$2:$F$36,A21,'Observed lines'!$G$2:$G$36,"<>") -> 1 | E21: =IF(D21=0,"",_xlfn.MINIFS('Observed lines'!$G$2:$G$36,'Observed lines'!$F$2:$F$36,A21)) -> 374.66 | F21: =IF(D21=0,"",_xlfn.MAXIFS('Observed lines'!$G$2:$G$36,'Observed lines'!$F$2:$F$36,A21)) -> 374.66 | G21: =IF(D21=0,"none seen",IF(E21=F21,TEXT(E21,"$#,##0.00"),TEXT(E21,"$#,##0.00")&" – "&TEXT(F21,"$#,##0.00"))) -> $374.66 | H21: seed + observed | I21: OK
