Workbook

Sheet README
A1: IDR Prep Studio v2 – Build Spec
A3: Version | B3: v2.0
A4: Date | B4: 2026-10-21
A5: Audience | B5: IT and software development.
A6: Purpose | B6: This workbook is the build spec for IDR Prep Studio v2. It lists every field, list, rule, table and server function. It also holds the trends seen in 4 real Notices of IDR Initiation.
A7: App | B7: Google Apps Script web app in oon-operating-model/idr-prep-studio/ (Code.gs, Index.html, Pdf.html, DemoData.gs).
A8: Not the CMS portal | B8: The Studio never connects to the federal IDR portal. The US desk copies the values into the portal by hand. Keep the "not the CMS portal" banner.
A9: Sources | B9: Notices DISP-7984427 and DISP-7986216 (initiated 10/15/2026), DISP-7997846 and DISP-7998956 (initiated 10/16/2026). Current schema: Code.gs. Build spec: spec-studio-v2.md. Field review: 17 ranked improvements.
A10: PHI rule | B10: This workbook holds no claim numbers, no dates of service and no account numbers. File names are shown as patterns, for example "EOB <account>.pdf". Business data is allowed: payer names, addresses and IDR emails, our billing entities, TIN, NPI, IDR entity names, service codes and descriptions. Do not add PHI to this file. Demo data must stay synthetic.
A11: How to use | B11: 1. Start with Fields. It lists each field in portal order with its key, type, rule and default.
B12: 2. Lists, Payers, BillingEntities and ServiceCodes hold the seed rows for the Options tab.
B13: 3. Trends and Observed lines show what the 4 notices contain. They justify the defaults.
B14: 4. Learning rules, Validation rules and Workflow are the requirements. Each row has an ID to cite in tickets.
B15: 5. Data model and API describe the tabs and server functions.
B16: 6. Backlog holds the user stories. Open questions lists what the business must answer.
A17: Formulas | B17: ServiceCodes (Times seen, QPA min and max) and Trends (Share) use formulas. They update when Observed lines change.
A18: Status legend | B18: Existing – in Code.gs today and unchanged.
B19: Changed – in Code.gs today; v2 changes it.
B20: New – added in v2.
B21: Planned – backlog item not yet built.
B22: Needs business – blocked on an answer in Open questions.
A23: Dispute statuses | B23: Draft, Ready for US desk, Returned, Filed. See Workflow.
A24: Orange cells | B24: A data-quality flag (Observed lines) or a field that needs a business answer.
A25: Sheets | B25: README, Fields, Lists, Payers, BillingEntities, ServiceCodes, Trends, Observed lines, Learning rules, Validation rules, Workflow, Data model, API, Backlog, Open questions.

Sheet Fields
A1: Page | B1: Section | C1: Portal label (exact text from the notice) | D1: Field key | E1: Type | F1: Required | G1: Validation rule | H1: Default (seeded) | I1: Learned default? (Y/N) | J1: Source list | K1: Auto-fill from | L1: Copy-desk order | M1: Notes
A2: Qualification · page 1 | B2: Qualification Questions | C2: Was the service in question provided prior to 1/1/2022? | D2: q_prior_2022 | E2: radio | F2: Yes | G2: One of Yes, No. Yes = hard stop (V11). | H2: No | I2: Y | J2: Yes/No (fixed) | L2: 1 | M2: Observed No 4/4.
A3: Qualification · page 1 | B3: Qualification Questions | C3: I'm a(n): | D3: q_acting_as | E3: radio | F3: Yes | G3: One of the 6 acting-as options. | H3: From billing entity (Health care facility) | I3: Y | J3: ActingAs (fixed) | K3: BillingEntity.acting_as | L3: 2 | M3: Entry label: "I am (or I am acting on behalf of) a:". Observed facility 3/4, provider 1/4.
A4: Qualification · page 1 | B4: Qualification Questions | C4: Tax ID: | D4: tin | E4: text | F4: Yes | G4: ^\d{9}$ (V09) | H4: From billing entity | I4: N | K4: BillingEntity.tin | L4: 3 | M4: New field. 9 digits, no dash.
A5: Qualification · page 1 | B5: Qualification Questions | C5: National Provider Identifier (NPI): | D5: npi | E5: text | F5: Yes | G5: ^\d{10}$ (V10) | H5: From billing entity | I5: N | K5: BillingEntity.npi | L5: 4 | M5: New field. 10 digits.
A6: Qualification · page 1 | B6: Qualification Questions | C6: Health Plan Type: | D6: q_plan_type | E6: combo | F6: Yes | G6: Free text allowed; typo check (V31). | H6: Either partially or fully self-insured ERISA group health plan | I6: Y | J6: HealthPlanType | L6: 5 | M6: Changed: select to combo. Observed 4/4. The 7 placeholders are removed.
A7: Qualification · page 1 | B7: Qualification Questions | C7: What are you disputing today? | D7: dispute_kind | E7: radio | F7: Yes | G7: One of Single dispute, A batched dispute, A bundled dispute. Warn if Single dispute and more than 1 distinct claim number (V15). | H7: A batched dispute | I7: Y | J7: DisputeKind (fixed) | L7: 9 | M7: New field. Shown on page 1 (spec section 4). On the notice it comes after the consent question, so its copy-desk order is after consent_waiver. Observed batched 3/4, single 1/4.
A8: Qualification · page 2 | B8: Qualification Questions | C8: When did the open negotiation period start? | D8: on_start_date | E8: date | F8: Yes | G8: YYYY-MM-DD; not in the future (V08). Deadline helper (V13, V14). | I8: N | L8: 6 | M8: Entry label: "Start Date of the Open Negotiation Period:". Helper text: "Open negotiation ends <date>. Initiate by <date> (<n> business days left)."
A9: Qualification · page 2 | B9: Qualification Questions | C9: Proof of Open Negotiation Documentation: | D9: on_evidence | E9: file | F9: Yes | G9: At least 1 file, under 45 MB (V24, V35). | I9: N | L9: 7 | M9: Category on_evidence. Names seen: "OMB <account>.pdf", "PROOF <account>.png", "<date> LLC NSA NEG LETTER C <account>.pdf". Suggest a name.
A10: Qualification · page 2 | B10: Qualification Questions | C10: Did the health care provider, health care facility, or provider of air ambulance services get consent from the participant, beneficiary, or enrollee to waive surprise billing protections for these items or services? | D10: consent_waiver | E10: radio | F10: Yes | G10: One of Yes, No. Yes = hard stop (V12). | H10: No | I10: Y | J10: Yes/No (fixed) | L10: 8 | M10: Observed No 4/4.
A11: Parties · page 3 | B11: Group Health Plan / Health Insurance Issuer / FEHB Carrier Information or TPA | C11: I'm a(n): | D11: plan_role | E11: radio | F11: Yes | G11: One of the 3 plan roles. | I11: N | J11: PlanRole (fixed) | L11: 10 | M11: Not printed on the notice. Entry label shown.
A12: Parties · page 3 | B12: Group Health Plan / Health Insurance Issuer / FEHB Carrier Information or TPA | C12: Name: | D12: plan_name | E12: combo | F12: Yes | G12: Free text allowed; typo check (V31). | I12: N | J12: Payer | L12: 11 | M12: Entry label: "Health Insurance Plan or Company:". Picking a payer fills the fields below (L03).
A13: Parties · page 3 | B13: Group Health Plan / Health Insurance Issuer / FEHB Carrier Information or TPA | C13: Mailing Address: | D13: plan_addr1 | E13: text | F13: Yes | I13: N | K13: Payer.addr1 | L13: 12
A14: Parties · page 3 | B14: Group Health Plan / Health Insurance Issuer / FEHB Carrier Information or TPA | C14: Mailing Address Line 2: | D14: plan_addr2 | E14: text | F14: No | I14: N | K14: Payer.addr2 | L14: 13 | M14: Line 2 is not printed on the notice.
A15: Parties · page 3 | B15: Group Health Plan / Health Insurance Issuer / FEHB Carrier Information or TPA | C15: City: | D15: plan_city | E15: text | F15: Yes | I15: N | K15: Payer.city | L15: 14
A16: Parties · page 3 | B16: Group Health Plan / Health Insurance Issuer / FEHB Carrier Information or TPA | C16: State: | D16: plan_state | E16: select | F16: Yes | G16: Strict select from State (V32). | I16: N | J16: State | K16: Payer.state | L16: 15
A17: Parties · page 3 | B17: Group Health Plan / Health Insurance Issuer / FEHB Carrier Information or TPA | C17: Zip Code: | D17: plan_zip | E17: zip | F17: Yes | G17: V02 | I17: N | K17: Payer.zip | L17: 16
A18: Parties · page 3 | B18: Group Health Plan / Health Insurance Issuer / FEHB Carrier Information or TPA | C18: Email: | D18: plan_email | E18: email | F18: Yes | G18: V04 | I18: N | K18: Payer.email | L18: 17
A19: Parties · page 3 | B19: Group Health Plan / Health Insurance Issuer / FEHB Carrier Information or TPA | C19: Phone: | D19: plan_phone | E19: phone | F19: Yes | G19: V03 | I19: N | K19: Payer.phone | L19: 18
A20: Parties · page 3 | B20: Group Health Plan / Health Insurance Issuer / FEHB Carrier Information or TPA | C20: Fax: | D20: plan_fax | E20: phone | F20: No | G20: V03 | I20: N | K20: Payer.fax | L20: 19 | M20: Blank on all 4 notices.
A21: Parties · page 3 | B21: Primary Point-of-contact | C21: Name: | D21: plan_p1_name | E21: text | F21: No | I21: N | L21: 20 | M21: Collapsed by default ("Add point of contact"). Empty on all 4 notices.
A22: Parties · page 3 | B22: Primary Point-of-contact | C22: Mailing Address: | D22: plan_p1_addr1 | E22: text | F22: No | I22: N | L22: 21
A23: Parties · page 3 | B23: Primary Point-of-contact | C23: Mailing Address Line 2: | D23: plan_p1_addr2 | E23: text | F23: No | I23: N | L23: 22
A24: Parties · page 3 | B24: Primary Point-of-contact | C24: City: | D24: plan_p1_city | E24: text | F24: No | I24: N | L24: 23
A25: Parties · page 3 | B25: Primary Point-of-contact | C25: State: | D25: plan_p1_state | E25: select | F25: No | G25: Strict select from State (V32). | I25: N | J25: State | L25: 24
A26: Parties · page 3 | B26: Primary Point-of-contact | C26: Zip Code: | D26: plan_p1_zip | E26: zip | F26: No | G26: V02 | I26: N | L26: 25
A27: Parties · page 3 | B27: Primary Point-of-contact | C27: Email: | D27: plan_p1_email | E27: email | F27: No | G27: V04 | I27: N | L27: 26
A28: Parties · page 3 | B28: Primary Point-of-contact | C28: Phone: | D28: plan_p1_phone | E28: phone | F28: No | G28: V03 | I28: N | L28: 27
A29: Parties · page 3 | B29: Secondary point-of-contact | C29: Name: | D29: plan_p2_name | E29: text | F29: No | I29: N | L29: 28 | M29: Collapsed by default ("Add point of contact"). Empty on all 4 notices.
A30: Parties · page 3 | B30: Secondary point-of-contact | C30: Mailing Address: | D30: plan_p2_addr1 | E30: text | F30: No | I30: N | L30: 29
A31: Parties · page 3 | B31: Secondary point-of-contact | C31: Mailing Address Line 2: | D31: plan_p2_addr2 | E31: text | F31: No | I31: N | L31: 30
A32: Parties · page 3 | B32: Secondary point-of-contact | C32: City: | D32: plan_p2_city | E32: text | F32: No | I32: N | L32: 31
A33: Parties · page 3 | B33: Secondary point-of-contact | C33: State: | D33: plan_p2_state | E33: select | F33: No | G33: Strict select from State (V32). | I33: N | J33: State | L33: 32
A34: Parties · page 3 | B34: Secondary point-of-contact | C34: Zip Code: | D34: plan_p2_zip | E34: zip | F34: No | G34: V02 | I34: N | L34: 33
A35: Parties · page 3 | B35: Secondary point-of-contact | C35: Email: | D35: plan_p2_email | E35: email | F35: No | G35: V04 | I35: N | L35: 34
A36: Parties · page 3 | B36: Secondary point-of-contact | C36: Phone: | D36: plan_p2_phone | E36: phone | F36: No | G36: V03 | I36: N | L36: 35
A37: Parties · page 3 | B37: Health Care Provider, Health Care Facility, or Provider of Air Ambulance Services Information or TPA | C37: Name: | D37: prov_name | E37: combo | F37: Yes | G37: Free text allowed; typo check (V31). | H37: SILVER ALLIANCE LLC | I37: Y | J37: BillingEntity | L37: 36 | M37: New field, at the top of the provider section. Picking it fills q_acting_as, tin, npi, prov_designation, prov_group_name and the provider contact fields (L03). Also the signature name.
A38: Parties · page 3 | B38: Health Care Provider, Health Care Facility, or Provider of Air Ambulance Services Information or TPA | C38: Select one of the Health Care Designations: | D38: prov_designation | E38: radio | F38: Yes | G38: One of the 3 designations. | H38: From billing entity | I38: N | J38: Designation (fixed) | K38: BillingEntity.acting_as | L38: 37 | M38: Not printed on the notice; the notice shows it as "I'm a(n):".
A39: Parties · page 3 | B39: Health Care Provider, Health Care Facility, or Provider of Air Ambulance Services Information or TPA | C39: Hospital, Facility or Group Name: | D39: prov_group_name | E39: text | F39: No | H39: From billing entity | I39: N | K39: BillingEntity.group_name | L39: 38 | M39: New field. Printed only for the provider entity (CAPITAL HEALTH PLLC).
A40: Parties · page 3 | B40: Health Care Provider, Health Care Facility, or Provider of Air Ambulance Services Information or TPA | C40: Mailing Address: | D40: prov_addr1 | E40: text | F40: Yes | H40: From billing entity | I40: N | K40: BillingEntity.addr1 | L40: 39 | M40: New field (key assumed: prov_ + contact suffix).
...

Sheet Lists
A1: List | B1: Value | C1: Label | D1: Data JSON | E1: Count observed | F1: Source | G1: Status
A2: YesNo | B2: Yes | E2: 0 | F2: fixed (Code.gs) | G2: Active
A3: YesNo | B3: No | E3: No: 4/4 on prior-2022, consent, third party | F3: fixed (Code.gs) | G3: Active
A4: ActingAs | B4: Group Health Plan | E4: 0 | F4: fixed (Code.gs) | G4: Active
A5: ActingAs | B5: Individual health insurance issuer | E5: 0 | F5: fixed (Code.gs) | G5: Active
A6: ActingAs | B6: Federal Employees Health Benefits (FEHB) carrier | E6: 0 | F6: fixed (Code.gs) | G6: Active
A7: ActingAs | B7: Health care provider | E7: 1 | F7: fixed (Code.gs) | G7: Active
A8: ActingAs | B8: Health care facility | E8: 3 | F8: fixed (Code.gs) | G8: Active
A9: ActingAs | B9: Provider of air ambulance services | E9: 0 | F9: fixed (Code.gs) | G9: Active
A10: PlanRole | B10: Group Health Plan | E10: 0 | F10: fixed (Code.gs) | G10: Active
A11: PlanRole | B11: Individual health insurance issuer | E11: 0 | F11: fixed (Code.gs) | G11: Active
A12: PlanRole | B12: Federal Employees Health Benefits (FEHB) carrier | E12: 0 | F12: fixed (Code.gs) | G12: Active
A13: Designation | B13: Health care provider | E13: 1 | F13: fixed (Code.gs) | G13: Active
A14: Designation | B14: Health care facility | E14: 3 | F14: fixed (Code.gs) | G14: Active
A15: Designation | B15: Provider of air ambulance services | E15: 0 | F15: fixed (Code.gs) | G15: Active
... A82: HealthPlanType | B82: Either partially or fully self-insured ERISA group health plan | E82: 4 | F82: seed | G82: Active
A83: Payer | B83: UMR | C83: UMR | D83: {"addr1": "PO BOX 30541", "addr2": "", "city": "SALT LAKE CITY", "state": "UT", "zip": "84130", "email": "idr@clearhealthcloud.com", "phone": "(877) 233-1800", "fax": ""} | E83: 1 | F83: seed | G83: Active
A84: Payer | B84: BLUECROSS BLUESHIELD | C84: BLUECROSS BLUESHIELD | D84: {"addr1": "PO BOX 660044", "addr2": "", "city": "Dallas", "state": "TX", "zip": "75266", "email": "nsa.disputes@bcbstx.com", "phone": "(800) 451-0287", "fax": ""} | E84: 1 | F84: seed | G84: Active
A85: Payer | B85: Cigna | C85: Cigna | D85: {"addr1": "P.O. BOX 182223", "addr2": "", "city": "CHATTANOOGA", "state": "TN", "zip": "37422-7223", "email": "nsaidr@multiplan.com", "phone": "(800) 244-6224", "fax": ""} | E85: 1 | F85: seed | G85: Active
A86: Payer | B86: United Healthcare | C86: United Healthcare | D86: {"addr1": "PO Box 30783", "addr2": "", "city": "Salt Lake City", "state": "UT", "zip": "84130-0783", "email": "uhg_idr_disputes@uhc.com", "phone": "(877) 842-3210", "fax": ""} | E86: 1 | F86: seed | G86: Active
A87: BillingEntity | B87: SILVER ALLIANCE LLC | C87: SILVER ALLIANCE LLC | D87: {"acting_as": "Health care facility", "tin": "862923814", "npi": "1972273233", "group_name": "", "addr1": "6049 S. Hulen St.", "addr2": "", "city": "Fort Worth", "state": "TX", "zip": "76132", "email": "cedarhill.negotiations@totalcare.us", "phone": "(817) 566-1232", "fax": ""} | E87: 3 | F87: seed | G87: Active
A88: BillingEntity | B88: CAPITAL HEALTH PLLC | C88: CAPITAL HEALTH PLLC | D88: {"acting_as": "Health care provider", "tin": "872524265", "npi": "1609548056", "group_name": "Totalcare ER, Cedar Hill", "addr1": "6049 S. Hulen St.", "addr2": "", "city": "Fort Worth", "state": "TX", "zip": "76132", "email": "cedarhill.negotiations@totalcare.us", "phone": "(817) 566-1232", "fax": ""} | E88: 1 | F88: seed | G88: Active
A89: IdrEntity | B89: Maximus Federal Services Inc | C89: Maximus Federal Services Inc | E89: 2 | F89: seed | G89: Active
A90: IdrEntity | B90: Capitol Bridge LLC | C90: Capitol Bridge LLC | E90: 1 | F90: seed | G90: Active
A91: IdrEntity | B91: Federal Hearings and Appeals Services, LLC | C91: Federal Hearings and Appeals Services, LLC | E91: 1 | F91: seed | G91: Active
A92: ServiceCode | B92: 99284 | C92: EMERGENCY ROOM SERVICE | D92: {"description": "EMERGENCY ROOM SERVICE"} | E92: 3 | F92: seed | G92: Active
A93: ServiceCode | B93: 10061 | C93: DRAINAGE OF SKIN ABSCESS | D93: {"description": "DRAINAGE OF SKIN ABSCESS"} | E93: 1 | F93: seed | G93: Active
A94: ServiceCode | B94: J3490 | C94: PHARMACY | D94: {"description": "PHARMACY"} | E94: 1 | F94: seed | G94: Active
A95: ServiceCode | B95: J0696 | C95: Injection, ceftriaxone sodium, per 250 mg | D95: {"description": "Injection, ceftriaxone sodium, per 250 mg"} | E95: 1 | F95: seed | G95: Active
A96: ServiceCode | B96: 99283 | C96: EMERGENCY ROOM SERVICE | D96: {"description": "EMERGENCY ROOM SERVICE"} | E96: 1 | F96: seed | G96: Active
A97: ServiceCode | B97: 94761 | C97: MEASURE BLOOD OXYGEN LEVEL | D97: {"description": "MEASURE BLOOD OXYGEN LEVEL"} | E97: 2 | F97: seed | G97: Active
A98: ServiceCode | B98: 12001 | C98: REPAIR- TRUNK/SCALP/NECK/AXIL/LIMBS <2.5 | D98: {"description": "REPAIR- TRUNK/SCALP/NECK/AXIL/LIMBS <2.5"} | E98: 1 | F98: seed | G98: Active
A99: ServiceCode | B99: A4670 | C99: AUTOMATIC BLOOD PRESSURE MONITOR | D99: {"description": "AUTOMATIC BLOOD PRESSURE MONITOR"} | E99: 2 | F99: seed | G99: Active
A100: ServiceCode | B100: A6413 | C100: ADHESIVE BANDAGE, FIRST-AID | D100: {"description": "ADHESIVE BANDAGE, FIRST-AID"} | E100: 2 | F100: seed | G100: Active
A101: ServiceCode | B101: A4930 | C101: GLOVES STERILE PER PAIR | D101: {"description": "GLOVES STERILE PER PAIR"} | E101: 1 | F101: seed | G101: Active
A102: ServiceCode | B102: A4248 | C102: CHLORHEXIDINE ANTISEPT | D102: {"description": "CHLORHEXIDINE ANTISEPT"} | E102: 1 | F102: seed | G102: Active
A103: ServiceCode | B103: 96372 | C103: THERAPY/PROPHYLAXIS/DIAGNOSIS INJECTION, SC/IM | D103: {"description": "THERAPY/PROPHYLAXIS/DIAGNOSIS INJECTION, SC/IM"} | E103: 1 | F103: seed | G103: Active
... A123: ServiceCode | B123: 99285 | C123: EMERGENCY ROOM SERVICE | D123: {"description": "EMERGENCY ROOM SERVICE"} | E123: 0 | F123: seed | G123: Active
A124: PosCode | B124: 23 | C124: Emergency room – hospital | E124: 25 | F124: seed | G124: Active
A125: PosCode | B125: 22 | C125: On campus-outpatient hospital | E125: 0 | F125: seed | G125: Active
...

Sheet Payers
A1: Name | B1: Mailing Address | C1: Mailing Address Line 2 | D1: City | E1: State | F1: Zip Code | G1: Email | H1: Phone | I1: Fax | J1: Times seen | K1: Seen on dispute
A2: UMR | B2: PO BOX 30541 | D2: SALT LAKE CITY | E2: UT | F2: 84130 | G2: idr@clearhealthcloud.com | H2: (877) 233-1800 | J2: 1 | K2: DISP-7986216
A3: BLUECROSS BLUESHIELD | B3: PO BOX 660044 | D3: Dallas | E3: TX | F3: 75266 | G3: nsa.disputes@bcbstx.com | H3: (800) 451-0287 | J3: 1 | K3: DISP-7998956
A4: Cigna | B4: P.O. BOX 182223 | D4: CHATTANOOGA | E4: TN | F4: 37422-7223 | G4: nsaidr@multiplan.com | H4: (800) 244-6224 | J4: 1 | K4: DISP-7997846
A5: United Healthcare | B5: PO Box 30783 | D5: Salt Lake City | E5: UT | F5: 84130-0783 | G5: uhg_idr_disputes@uhc.com | H5: (877) 842-3210 | J5: 1 | K5: DISP-7984427

Sheet BillingEntities
A1: name | B1: acting_as | C1: tin | D1: npi | E1: group_name | F1: addr1 | G1: addr2 | H1: city | I1: state | J1: zip | K1: email | L1: phone | M1: fax | N1: Times seen | O1: Variants seen
A2: SILVER ALLIANCE LLC | B2: Health care facility | C2: 862923814 | D2: 1972273233 | F2: 6049 S. Hulen St. | H2: Fort Worth | I2: TX | J2: 76132 | K2: cedarhill.negotiations@totalcare.us | L2: (817) 566-1232 | N2: 3 | O2: Also written "SILVER ALLIANCE,LLC" and "6049 S. Hulen St" (no period) on DISP-7986216.
A3: CAPITAL HEALTH PLLC | B3: Health care provider | C3: 872524265 | D3: 1609548056 | E3: Totalcare ER, Cedar Hill | F3: 6049 S. Hulen St. | H3: Fort Worth | I3: TX | J3: 76132 | K3: cedarhill.negotiations@totalcare.us | L3: (817) 566-1232 | N3: 1

Sheet ServiceCodes
A1: Code | B1: Description | C1: Times seen | D1: Lines with a QPA | E1: QPA min | F1: QPA max | G1: Typical QPA range seen | H1: Source
A2: 99284 | B2: EMERGENCY ROOM SERVICE | C2: =COUNTIF('Observed lines'!$F$2:$F$36,A2) -> 3 | D2: =COUNTIFS('Observed lines'!$F$2:$F$36,A2,'Observed lines'!$G$2:$G$36,"<>") -> 2 | E2: =IF(D2=0,"",_xlfn.MINIFS('Observed lines'!$G$2:$G$36,'Observed lines'!$F$2:$F$36,A2)) -> 250.3 | F2: =IF(D2=0,"",_xlfn.MAXIFS('Observed lines'!$G$2:$G$36,'Observed lines'!$F$2:$F$36,A2)) -> 1052.46 | G2: =IF(D2=0,"none seen",IF(E2=F2,TEXT(E2,"$#,##0.00"),TEXT(E2,"$#,##0.00")&" – "&TEXT(F2,"$#,##0.00"))) -> $250.30 – $1,052.46 | H2: observed
A3: 10061 | B3: DRAINAGE OF SKIN ABSCESS | C3: =COUNTIF('Observed lines'!$F$2:$F$36,A3) -> 1 | D3: =COUNTIFS('Observed lines'!$F$2:$F$36,A3,'Observed lines'!$G$2:$G$36,"<>") -> 1 | E3: =IF(D3=0,"",_xlfn.MINIFS('Observed lines'!$G$2:$G$36,'Observed lines'!$F$2:$F$36,A3)) -> 775.52 | F3: =IF(D3=0,"",_xlfn.MAXIFS('Observed lines'!$G$2:$G$36,'Observed lines'!$F$2:$F$36,A3)) -> 775.52 | G3: =IF(D3=0,"none seen",IF(E3=F3,TEXT(E3,"$#,##0.00"),TEXT(E3,"$#,##0.00")&" – "&TEXT(F3,"$#,##0.00"))) -> $775.52 | H3: observed
A4: J3490 | B4: PHARMACY | C4: =COUNTIF('Observed lines'!$F$2:$F$36,A4) -> 1 | D4: =COUNTIFS('Observed lines'!$F$2:$F$36,A4,'Observed lines'!$G$2:$G$36,"<>") -> 1 | E4: =IF(D4=0,"",_xlfn.MINIFS('Observed lines'!$G$2:$G$36,'Observed lines'!$F$2:$F$36,A4)) -> 96.71 | F4: =IF(D4=0,"",_xlfn.MAXIFS('Observed lines'!$G$2:$G$36,'Observed lines'!$F$2:$F$36,A4)) -> 96.71 | G4: =IF(D4=0,"none seen",IF(E4=F4,TEXT(E4,"$#,##0.00"),TEXT(E4,"$#,##0.00")&" – "&TEXT(F4,"$#,##0.00"))) -> $96.71 | H4: observed
A5: J0696 | B5: Injection, ceftriaxone sodium, per 250 mg | C5: =COUNTIF('Observed lines'!$F$2:$F$36,A5) -> 1 | D5: =COUNTIFS('Observed lines'!$F$2:$F$36,A5,'Observed lines'!$G$2:$G$36,"<>") -> 1 | E5: =IF(D5=0,"",_xlfn.MINIFS('Observed lines'!$G$2:$G$36,'Observed lines'!$F$2:$F$36,A5)) -> 25.34 | F5: =IF(D5=0,"",_xlfn.MAXIFS('Observed lines'!$G$2:$G$36,'Observed lines'!$F$2:$F$36,A5)) -> 25.34 | G5: =IF(D5=0,"none seen",IF(E5=F5,TEXT(E5,"$#,##0.00"),TEXT(E5,"$#,##0.00")&" – "&TEXT(F5,"$#,##0.00"))) -> $25.34 | H5: observed
A6: 99283 | B6: EMERGENCY ROOM SERVICE | C6: =COUNTIF('Observed lines'!$F$2:$F$36,A6) -> 1 | D6: =COUNTIFS('Observed lines'!$F$2:$F$36,A6,'Observed lines'!$G$2:$G$36,"<>") -> 1 | E6: =IF(D6=0,"",_xlfn.MINIFS('Observed lines'!$G$2:$G$36,'Observed lines'!$F$2:$F$36,A6)) -> 905.44 | F6: =IF(D6=0,"",_xlfn.MAXIFS('Observed lines'!$G$2:$G$36,'Observed lines'!$F$2:$F$36,A6)) -> 905.44 | G6: =IF(D6=0,"none seen",IF(E6=F6,TEXT(E6,"$#,##0.00"),TEXT(E6,"$#,##0.00")&" – "&TEXT(F6,"$#,##0.00"))) -> $905.44 | H6: observed
A7: 94761 | B7: MEASURE BLOOD OXYGEN LEVEL | C7: =COUNTIF('Observed lines'!$F$2:$F$36,A7) -> 2 | D7: =COUNTIFS('Observed lines'!$F$2:$F$36,A7,'Observed lines'!$G$2:$G$36,"<>") -> 2 | E7: =IF(D7=0,"",_xlfn.MINIFS('Observed lines'!$G$2:$G$36,'Observed lines'!$F$2:$F$36,A7)) -> 29.41 | F7: =IF(D7=0,"",_xlfn.MAXIFS('Observed lines'!$G$2:$G$36,'Observed lines'!$F$2:$F$36,A7)) -> 143.2 | G7: =IF(D7=0,"none seen",IF(E7=F7,TEXT(E7,"$#,##0.00"),TEXT(E7,"$#,##0.00")&" – "&TEXT(F7,"$#,##0.00"))) -> $29.41 – $143.20 | H7: observed
A8: 12001 | B8: REPAIR- TRUNK/SCALP/NECK/AXIL/LIMBS <2.5 | C8: =COUNTIF('Observed lines'!$F$2:$F$36,A8) -> 1 | D8: =COUNTIFS('Observed lines'!$F$2:$F$36,A8,'Observed lines'!$G$2:$G$36,"<>") -> 1 | E8: =IF(D8=0,"",_xlfn.MINIFS('Observed lines'!$G$2:$G$36,'Observed lines'!$F$2:$F$36,A8)) -> 447.17 | F8: =IF(D8=0,"",_xlfn.MAXIFS('Observed lines'!$G$2:$G$36,'Observed lines'!$F$2:$F$36,A8)) -> 447.17 | G8: =IF(D8=0,"none seen",IF(E8=F8,TEXT(E8,"$#,##0.00"),TEXT(E8,"$#,##0.00")&" – "&TEXT(F8,"$#,##0.00"))) -> $447.17 | H8: observed
A9: A4670 | B9: AUTOMATIC BLOOD PRESSURE MONITOR | C9: =COUNTIF('Observed lines'!$F$2:$F$36,A9) -> 2 | D9: =COUNTIFS('Observed lines'!$F$2:$F$36,A9,'Observed lines'!$G$2:$G$36,"<>") -> 2 | E9: =IF(D9=0,"",_xlfn.MINIFS('Observed lines'!$G$2:$G$36,'Observed lines'!$F$2:$F$36,A9)) -> 2.12 | F9: =IF(D9=0,"",_xlfn.MAXIFS('Observed lines'!$G$2:$G$36,'Observed lines'!$F$2:$F$36,A9)) -> 10.32 | G9: =IF(D9=0,"none seen",IF(E9=F9,TEXT(E9,"$#,##0.00"),TEXT(E9,"$#,##0.00")&" – "&TEXT(F9,"$#,##0.00"))) -> $2.12 – $10.32 | H9: observed
A10: A6413 | B10: ADHESIVE BANDAGE, FIRST-AID | C10: =COUNTIF('Observed lines'!$F$2:$F$36,A10) -> 2 | D10: =COUNTIFS('Observed lines'!$F$2:$F$36,A10,'Observed lines'!$G$2:$G$36,"<>") -> 2 | E10: =IF(D10=0,"",_xlfn.MINIFS('Observed lines'!$G$2:$G$36,'Observed lines'!$F$2:$F$36,A10)) -> 1.34 | F10: =IF(D10=0,"",_xlfn.MAXIFS('Observed lines'!$G$2:$G$36,'Observed lines'!$F$2:$F$36,A10)) -> 6.5 | G10: =IF(D10=0,"none seen",IF(E10=F10,TEXT(E10,"$#,##0.00"),TEXT(E10,"$#,##0.00")&" – "&TEXT(F10,"$#,##0.00"))) -> $1.34 – $6.50 | H10: observed
A11: A4930 | B11: GLOVES STERILE PER PAIR | C11: =COUNTIF('Observed lines'!$F$2:$F$36,A11) -> 1 | D11: =COUNTIFS('Observed lines'!$F$2:$F$36,A11,'Observed lines'!$G$2:$G$36,"<>") -> 1 | E11: =IF(D11=0,"",_xlfn.MINIFS('Observed lines'!$G$2:$G$36,'Observed lines'!$F$2:$F$36,A11)) -> 28.87 | F11: =IF(D11=0,"",_xlfn.MAXIFS('Observed lines'!$G$2:$G$36,'Observed lines'!$F$2:$F$36,A11)) -> 28.87 | G11: =IF(D11=0,"none seen",IF(E11=F11,TEXT(E11,"$#,##0.00"),TEXT(E11,"$#,##0.00")&" – "&TEXT(F11,"$#,##0.00"))) -> $28.87 | H11: observed
A12: A4248 | B12: CHLORHEXIDINE ANTISEPT | C12: =COUNTIF('Observed lines'!$F$2:$F$36,A12) -> 1 | D12: =COUNTIFS('Observed lines'!$F$2:$F$36,A12,'Observed lines'!$G$2:$G$36,"<>") -> 1 | E12: =IF(D12=0,"",_xlfn.MINIFS('Observed lines'!$G$2:$G$36,'Observed lines'!$F$2:$F$36,A12)) -> 1.91 | F12: =IF(D12=0,"",_xlfn.MAXIFS('Observed lines'!$G$2:$G$36,'Observed lines'!$F$2:$F$36,A12)) -> 1.91 | G12: =IF(D12=0,"none seen",IF(E12=F12,TEXT(E12,"$#,##0.00"),TEXT(E12,"$#,##0.00")&" – "&TEXT(F12,"$#,##0.00"))) -> $1.91 | H12: observed
A13: 96372 | B13: THERAPY/PROPHYLAXIS/DIAGNOSIS INJECTION, SC/IM | C13: =COUNTIF('Observed lines'!$F$2:$F$36,A13) -> 1 | D13: =COUNTIFS('Observed lines'!$F$2:$F$36,A13,'Observed lines'!$G$2:$G$36,"<>") -> 1 | E13: =IF(D13=0,"",_xlfn.MINIFS('Observed lines'!$G$2:$G$36,'Observed lines'!$F$2:$F$36,A13)) -> 37.78 | F13: =IF(D13=0,"",_xlfn.MAXIFS('Observed lines'!$G$2:$G$36,'Observed lines'!$F$2:$F$36,A13)) -> 37.78 | G13: =IF(D13=0,"none seen",IF(E13=F13,TEXT(E13,"$#,##0.00"),TEXT(E13,"$#,##0.00")&" – "&TEXT(F13,"$#,##0.00"))) -> $37.78 | H13: observed
... A33: 99285 | B33: EMERGENCY ROOM SERVICE | C33: =COUNTIF('Observed lines'!$F$2:$F$36,A33) -> 0 | D33: =COUNTIFS('Observed lines'!$F$2:$F$36,A33,'Observed lines'!$G$2:$G$36,"<>") -> 0 | E33: =IF(D33=0,"",_xlfn.MINIFS('Observed lines'!$G$2:$G$36,'Observed lines'!$F$2:$F$36,A33)) | F33: =IF(D33=0,"",_xlfn.MAXIFS('Observed lines'!$G$2:$G$36,'Observed lines'!$F$2:$F$36,A33)) | G33: =IF(D33=0,"none seen",IF(E33=F33,TEXT(E33,"$#,##0.00"),TEXT(E33,"$#,##0.00")&" – "&TEXT(F33,"$#,##0.00"))) -> none seen | H33: seed (not seen)
A35: Note | B35: Times seen, QPA min and QPA max are formulas over the Observed lines sheet. Lines with a blank QPA (DISP-7998956 lines 2–11) count as seen but are left out of the range.

Sheet Trends
A1: Portal field | B1: Observed value | C1: Count | D1: Out of | E1: Share | F1: Unit | G1: Studio action
A2: Was the service in question provided prior to 1/1/2022? | B2: No | C2: 4 | D2: 4 | E2: =IF(OR(C2="",D2=""),"",C2/D2) -> 1 | F2: notices | G2: Default No; Yes = hard stop.
A3: I'm a(n): | B3: Health care facility | C3: 3 | D3: 4 | E3: =IF(OR(C3="",D3=""),"",C3/D3) -> 0.75 | F3: notices | G3: Comes from the billing entity profile.
A4: I'm a(n): | B4: Health care provider | C4: 1 | D4: 4 | E4: =IF(OR(C4="",D4=""),"",C4/D4) -> 0.25 | F4: notices | G4: Comes from the billing entity profile.
A5: Tax ID / NPI | B5: Facility 862923814 / 1972273233 | C5: 3 | D5: 4 | E5: =IF(OR(C5="",D5=""),"",C5/D5) -> 0.75 | F5: notices | G5: New fields tin and npi, filled from the billing entity.
A6: Tax ID / NPI | B6: Provider 872524265 / 1609548056 | C6: 1 | D6: 4 | E6: =IF(OR(C6="",D6=""),"",C6/D6) -> 0.25 | F6: notices | G6: New fields tin and npi, filled from the billing entity.
A7: Health Plan Type: | B7: Either partially or fully self-insured ERISA group health plan | C7: 4 | D7: 4 | E7: =IF(OR(C7="",D7=""),"",C7/D7) -> 1 | F7: notices | G7: First real option; default.
A8: When did the open negotiation period start? | B8: 09/01/2026 | C8: 2 | D8: 4 | E8: =IF(OR(C8="",D8=""),"",C8/D8) -> 0.5 | F8: notices | G8: Deadline helper. Initiated on the last day of open negotiation.
A9: When did the open negotiation period start? | B9: 09/02/2026 | C9: 2 | D9: 4 | E9: =IF(OR(C9="",D9=""),"",C9/D9) -> 0.5 | F9: notices | G9: Deadline helper. Initiated on the last day of open negotiation.
A10: Proof of Open Negotiation Documentation: | B10: "OMB <account>.pdf" | C10: 2 | D10: 4 | E10: =IF(OR(C10="",D10=""),"",C10/D10) -> 0.5 | F10: notices | G10: Keep upload; suggest a name.
A11: Proof of Open Negotiation Documentation: | B11: "PROOF <account>.png" | C11: 1 | D11: 4 | E11: =IF(OR(C11="",D11=""),"",C11/D11) -> 0.25 | F11: notices | G11: Keep upload; suggest a name.
A12: Proof of Open Negotiation Documentation: | B12: "<date> LLC NSA NEG LETTER C <account>.pdf" | C12: 1 | D12: 4 | E12: =IF(OR(C12="",D12=""),"",C12/D12) -> 0.25 | F12: notices | G12: Keep upload; suggest a name.
A13: Consent to waive surprise billing protections | B13: No | C13: 4 | D13: 4 | E13: =IF(OR(C13="",D13=""),"",C13/D13) -> 1 | F13: notices | G13: Default No; Yes = hard stop.
... A39: Data quality | B39: Line with blank claim number, date, QPA, POS and location | C39: 10 | D39: 35 | E39: =IF(OR(C39="",D39=""),"",C39/D39) -> 0.28571429 | F39: lines | G39: Require these on every line. All blanks are DISP-7998956 lines 2–11.
A40: Lines per dispute | B40: 4, 7, 13 and 11 lines | C40: 35 | E40: =IF(OR(C40="",D40=""),"",C40/D40) | F40: lines in 4 notices | G40: Up to 50 lines per dispute.
A41: Deadline (computed) | B41: ON start 09/01/2026 → ON ends 10/15/2026 → initiate by 10/21/2026 | G41: 30 business days from the day after the start; then 4 business days. Labor Day and Columbus Day skipped.
A42: Deadline (computed) | B42: ON start 09/02/2026 → ON ends 10/16/2026 → initiate by 10/22/2026 | G42: 30 business days from the day after the start; then 4 business days. Labor Day and Columbus Day skipped.

Sheet Observed lines
A1: Dispute ref | B1: Payer | C1: Billing entity | D1: Line no | E1: Description | F1: Service code | G1: QPA | H1: Cost sharing | I1: Initial payment | J1: Item type | K1: POS | L1: Location | M1: IDR entity | N1: Data-quality flag
A2: DISP-7997846 | B2: Cigna | C2: SILVER ALLIANCE LLC | D2: 1 | E2: EMERGENCY ROOM SERVICE | F2: 99284 | G2: 1052.46 | H2: 0 | I2: 1052.46 | J2: Emergency item(s)/service(s) | K2: 23 | L2: TX | M2: Maximus Federal Services Inc
A3: DISP-7997846 | B3: Cigna | C3: SILVER ALLIANCE LLC | D3: 2 | E3: DRAINAGE OF SKIN ABSCESS | F3: 10061 | G3: 775.52 | H3: 0 | I3: 775.52 | J3: Emergency item(s)/service(s) | K3: 23 | L3: TX | M3: Maximus Federal Services Inc
A4: DISP-7997846 | B4: Cigna | C4: SILVER ALLIANCE LLC | D4: 3 | E4: PHARMACY | F4: J3490 | G4: 96.71 | H4: 0 | I4: 96.71 | J4: Emergency item(s)/service(s) | K4: 23 | L4: TX | M4: Maximus Federal Services Inc
A5: DISP-7997846 | B5: Cigna | C5: SILVER ALLIANCE LLC | D5: 4 | E5: Injection, ceftriaxone sodium, per 250 mg | F5: J0696 | G5: 25.34 | H5: 0 | I5: 25.34 | J5: Emergency item(s)/service(s) | K5: 23 | L5: TX | M5: Maximus Federal Services Inc
A6: DISP-7986216 | B6: UMR | C6: SILVER ALLIANCE,LLC | D6: 1 | E6: EMERGENCY ROOM SERVICE | F6: 99283 | G6: 905.44 | H6: 905.44 | I6: 0 | J6: Emergency item(s)/service(s) | K6: 23 | L6: TX | M6: Capitol Bridge LLC | N6: Entity name written "SILVER ALLIANCE,LLC".
A7: DISP-7986216 | B7: UMR | C7: SILVER ALLIANCE,LLC | D7: 2 | E7: MEASURE BLOOD OXYGEN LEVEL | F7: 94761 | G7: 143.2 | H7: 143.2 | I7: 0 | J7: Emergency item(s)/service(s) | K7: 23 | L7: TX | M7: Capitol Bridge LLC | N7: Entity name written "SILVER ALLIANCE,LLC".
A8: DISP-7986216 | B8: UMR | C8: SILVER ALLIANCE,LLC | D8: 3 | E8: REPAIR- TRUNK/SCALP/NECK/AXIL/LIMBS <2.5 | F8: 12001 | G8: 447.17 | H8: 447.17 | I8: 0 | J8: Emergency item(s)/service(s) | K8: 23 | L8: TX | M8: Capitol Bridge LLC | N8: Entity name written "SILVER ALLIANCE,LLC".
A9: DISP-7986216 | B9: UMR | C9: SILVER ALLIANCE,LLC | D9: 4 | E9: AUTOMATIC BLOOD PRESSURE MONITOR | F9: A4670 | G9: 10.32 | H9: 10.32 | I9: 0 | J9: Emergency item(s)/service(s) | K9: 23 | L9: TX | M9: Capitol Bridge LLC | N9: Entity name written "SILVER ALLIANCE,LLC".
A10: DISP-7986216 | B10: UMR | C10: SILVER ALLIANCE,LLC | D10: 5 | E10: ADHESIVE BANDAGE, FIRST-AID | F10: A6413 | G10: 6.5 | H10: 6.5 | I10: 0 | J10: Emergency item(s)/service(s) | K10: 23 | L10: TX | M10: Capitol Bridge LLC | N10: Entity name written "SILVER ALLIANCE,LLC".
A11: DISP-7986216 | B11: UMR | C11: SILVER ALLIANCE,LLC | D11: 6 | E11: GLOVES STERILE PER PAIR | F11: A4930 | G11: 28.87 | H11: 28.87 | I11: 0 | J11: Emergency item(s)/service(s) | K11: 23 | L11: TX | M11: Capitol Bridge LLC | N11: Entity name written "SILVER ALLIANCE,LLC".
A12: DISP-7986216 | B12: UMR | C12: SILVER ALLIANCE,LLC | D12: 7 | E12: CHLORHEXIDINE ANTISEPT | F12: A4248 | G12: 1.91 | H12: 1.91 | I12: 0 | J12: Emergency item(s)/service(s) | K12: 23 | L12: TX | M12: Capitol Bridge LLC | N12: Entity name written "SILVER ALLIANCE,LLC".
A13: DISP-7984427 | B13: United Healthcare | C13: SILVER ALLIANCE LLC | D13: 1 | E13: EMERGENCY ROOM SERVICE | F13: 99284 | G13: 250.3 | H13: 0 | I13: 250.3 | J13: Emergency item(s)/service(s) | K13: 23 | L13: TX | M13: Maximus Federal Services Inc
A14: DISP-7984427 | B14: United Healthcare | C14: SILVER ALLIANCE LLC | D14: 2 | E14: MEASURE BLOOD OXYGEN LEVEL | F14: 94761 | G14: 29.41 | H14: 0 | I14: 29.41 | J14: Emergency item(s)/service(s) | K14: 23 | L14: TX | M14: Maximus Federal Services Inc
A15: DISP-7984427 | B15: United Healthcare | C15: SILVER ALLIANCE LLC | D15: 3 | E15: THERAPY/PROPHYLAXIS/DIAGNOSIS INJECTION, SC/IM | F15: 96372 | G15: 37.78 | H15: 0 | I15: 37.78 | J15: Emergency item(s)/service(s) | K15: 23 | L15: TX | M15: Maximus Federal Services Inc
A16: DISP-7984427 | B16: United Healthcare | C16: SILVER ALLIANCE LLC | D16: 4 | E16: URINE PREGNANCY TEST | F16: 81025 | G16: 17.04 | H16: 0 | I16: 17.04 | J16: Emergency item(s)/service(s) | K16: 23 | L16: TX | M16: Maximus Federal Services Inc
A17: DISP-7984427 | B17: United Healthcare | C17: SILVER ALLIANCE LLC | D17: 5 | E17: CT NECK SPINE W/O DYE | F17: 72125 | G17: 374.66 | H17: 350 | I17: 24.66 | J17: Emergency item(s)/service(s) | K17: 23 | L17: TX | M17: Maximus Federal Services Inc
A18: DISP-7984427 | B18: United Healthcare | C18: SILVER ALLIANCE LLC | D18: 6 | E18: CT HEAD/BRAIN W/O DYE | F18: 70450 | G18: 348.35 | H18: 0 | I18: 348.35 | J18: Emergency item(s)/service(s) | K18: 23 | L18: TX | M18: Maximus Federal Services Inc
A19: DISP-7984427 | B19: United Healthcare | C19: SILVER ALLIANCE LLC | D19: 7 | E19: Computed tomography, thoracic spine | F19: 72128 | G19: 228.66 | H19: 0 | I19: 228.66 | J19: Emergency item(s)/service(s) | K19: 23 | L19: TX | M19: Maximus Federal Services Inc
A20: DISP-7984427 | B20: United Healthcare | C20: SILVER ALLIANCE LLC | D20: 8 | E20: AUTOMATIC BLOOD PRESSURE MONITOR | F20: A4670 | G20: 2.12 | H20: 0 | I20: 2.12 | J20: Emergency item(s)/service(s) | K20: 23 | L20: TX | M20: Maximus Federal Services Inc
A21: DISP-7984427 | B21: United Healthcare | C21: SILVER ALLIANCE LLC | D21: 9 | E21: Injection, ketorolac tromethamine, per 15 mg | F21: J1885 | G21: 5.26 | H21: 0 | I21: 5.26 | J21: Emergency item(s)/service(s) | K21: 23 | L21: TX | M21: Maximus Federal Services Inc
A22: DISP-7984427 | B22: United Healthcare | C22: SILVER ALLIANCE LLC | D22: 10 | E22: NEEDLES ONLY STERILE ANY SIZE EACH | F22: A4215 | G22: 2.59 | H22: 0 | I22: 2.59 | J22: Emergency item(s)/service(s) | K22: 23 | L22: TX | M22: Maximus Federal Services Inc
A23: DISP-7984427 | B23: United Healthcare | C23: SILVER ALLIANCE LLC | D23: 11 | E23: ADHESIVE BANDAGE, FIRST-AID | F23: A6413 | G23: 1.34 | H23: 0 | I23: 1.34 | J23: Emergency item(s)/service(s) | K23: 23 | L23: TX | M23: Maximus Federal Services Inc
A24: DISP-7984427 | B24: United Healthcare | C24: SILVER ALLIANCE LLC | D24: 12 | E24: SYRINGE WITH OR WITHOUT NEEDLE EACH | F24: A4657 | G24: 9.11 | H24: 0 | I24: 9.11 | J24: Emergency item(s)/service(s) | K24: 23 | L24: TX | M24: Maximus Federal Services Inc
... A26: DISP-7998956 | B26: BLUECROSS BLUESHIELD | C26: CAPITAL HEALTH PLLC | D26: 1 | E26: ASSAY OF AMYLASE | F26: 82150 | G26: 220.31 | H26: 4.72 | I26: 215.59 | J26: Emergency item(s)/service(s) | K26: 23 | L26: TX | M26: Federal Hearings and Appeals Services, LLC
A27: DISP-7998956 | B27: BLUECROSS BLUESHIELD | C27: CAPITAL HEALTH PLLC | D27: 2 | E27: EMERGENCY ROOM SERVICE | F27: 99284 | J27: Emergency item(s)/service(s) | M27: Federal Hearings and Appeals Services, LLC | N27: Blank claim number; blank date of service; QPA "$" only; no QPA documentation; cost sharing "$" only; initial payment "N/A"; blank POS; blank location.
A28: DISP-7998956 | B28: BLUECROSS BLUESHIELD | C28: CAPITAL HEALTH PLLC | D28: 3 | E28: URINALYSIS, AUTO, W/O SCOPE | F28: 81003 | J28: Emergency item(s)/service(s) | M28: Federal Hearings and Appeals Services, LLC | N28: Blank claim number; blank date of service; QPA "$" only; no QPA documentation; cost sharing "$" only; initial payment "N/A"; blank POS; blank location.
A29: DISP-7998956 | B29: BLUECROSS BLUESHIELD | C29: CAPITAL HEALTH PLLC | D29: 4 | E29: URINE PREGNANCY TEST | F29: 81025 | J29: Emergency item(s)/service(s) | M29: Federal Hearings and Appeals Services, LLC | N29: Blank claim number; blank date of service; QPA "$" only; no QPA documentation; cost sharing "$" only; initial payment "N/A"; blank POS; blank location.
A30: DISP-7998956 | B30: BLUECROSS BLUESHIELD | C30: CAPITAL HEALTH PLLC | D30: 5 | E30: COMPLETE CBC W/AUTO DIFF WBC | F30: 85025 | J30: Emergency item(s)/service(s) | M30: Federal Hearings and Appeals Services, LLC | N30: Blank claim number; blank date of service; QPA "$" only; no QPA documentation; cost sharing "$" only; initial payment "N/A"; blank POS; blank location.
A31: DISP-7998956 | B31: BLUECROSS BLUESHIELD | C31: CAPITAL HEALTH PLLC | D31: 6 | E31: ELECTROLYTE PANEL | F31: 80051 | J31: Emergency item(s)/service(s) | M31: Federal Hearings and Appeals Services, LLC | N31: Blank claim number; blank date of service; QPA "$" only; no QPA documentation; cost sharing "$" only; initial payment "N/A"; blank POS; blank location.
A32: DISP-7998956 | B32: BLUECROSS BLUESHIELD | C32: CAPITAL HEALTH PLLC | D32: 7 | E32: ASSAY OF CK (CPK) | F32: 82550 | J32: Emergency item(s)/service(s) | M32: Federal Hearings and Appeals Services, LLC | N32: Blank claim number; blank date of service; QPA "$" only; no QPA documentation; cost sharing "$" only; initial payment "N/A"; blank POS; blank location.
A33: DISP-7998956 | B33: BLUECROSS BLUESHIELD | C33: CAPITAL HEALTH PLLC | D33: 8 | E33: ASSAY OF CREATININE | F33: 82565 | J33: Emergency item(s)/service(s) | M33: Federal Hearings and Appeals Services, LLC | N33: Blank claim number; blank date of service; QPA "$" only; no QPA documentation; cost sharing "$" only; initial payment "N/A"; blank POS; blank location.
A34: DISP-7998956 | B34: BLUECROSS BLUESHIELD | C34: CAPITAL HEALTH PLLC | D34: 9 | E34: ASSAY, GLUCOSE, BLOOD QUANT | F34: 82947 | J34: Emergency item(s)/service(s) | M34: Federal Hearings and Appeals Services, LLC | N34: Blank claim number; blank date of service; QPA "$" only; no QPA documentation; cost sharing "$" only; initial payment "N/A"; blank POS; blank location.
A35: DISP-7998956 | B35: BLUECROSS BLUESHIELD | C35: CAPITAL HEALTH PLLC | D35: 10 | E35: ASSAY OF UREA NITROGEN | F35: 84520 | J35: Emergency item(s)/service(s) | M35: Federal Hearings and Appeals Services, LLC | N35: Blank claim number; blank date of service; QPA "$" only; no QPA documentation; cost sharing "$" only; initial payment "N/A"; blank POS; blank location.
A36: DISP-7998956 | B36: BLUECROSS BLUESHIELD | C36: CAPITAL HEALTH PLLC | D36: 11 | E36: HEPATIC FUNCTION PANEL | F36: 80076 | J36: Emergency item(s)/service(s) | M36: Federal Hearings and Appeals Services, LLC | N36: Blank claim number; blank date of service; QPA "$" only; no QPA documentation; cost sharing "$" only; initial payment "N/A"; blank POS; blank location.

Sheet Learning rules
A1: ID | B1: Requirement | C1: Acceptance criteria | D1: Priority
A2: L01 | B2: The Options tab is the single source for every list. Columns: List | Value | Label | Data | Count | LastUsed | Source | Status | AddedBy | AddedAt. | C2: setup() adds the missing columns without losing rows. Every list in the app is read from Options. | D2: Do first
A3: L02 | B3: Combo fields allow free typing with suggestions ranked by Count, then LastUsed. Fields: plan_name, prov_name, q_plan_type, idr_entity, service_code, modifiers, pos_code, Team, Owner, ReturnReason. State stays a strict select. | C3: Typing 2 letters shows matching Active values, most used first. A new value can be saved. | D3: Do first
A4: L03 | B4: Learn on save: saveDispute, saveLine and returnDispute call learn_(list, value, data). A new value adds a row with Source=learned and Count=1. An existing value gets Count+1 and LastUsed=now. | C4: Saving a dispute with a new payer adds one row. Saving again increases Count. No duplicate rows. | D4: Do first
A5: L04 | B5: For profile lists (Payer, BillingEntity, ServiceCode), learn_() updates the Data JSON with the latest non-empty profile fields. | C5: Changing a payer phone and saving updates Payer Data.phone. Empty fields do not erase stored values. | D5: Do first
A6: L05 | B6: learn_() clears the options cache, so new values show for everyone on the next page load. | C6: A value saved by user A appears for user B after a reload. | D6: Do first
A7: L06 | B7: Profile auto-fill: a payer fills the plan contact fields. A billing entity fills q_acting_as, tin, npi, prov_designation, prov_group_name and provider contact fields. A service code fills description. | C7: Only empty fields are filled. "Refill from <name>" overwrites. A note "Filled from the address book" shows. | D7: Do first
A8: L07 | B8: Learned defaults: suggestDefaults_() finds the most-used value in the last DefaultWindow (50) saved records. If its share is at least DefaultShare (0.8), it is the default. Otherwise the seeded default is used. | C8: Computed in getBootstrap, cached 10 minutes. Fields: q_prior_2022, q_acting_as, q_plan_type, consent_waiver, dispute_kind, prov_name, idr_entity, third_party_attest, item_types, pos_code, location, modifiers. | D8: Do next
A9: L08 | B9: Defaults are pre-selected on a new dispute and a new line and marked with a "default" chip. The user can change them. | C9: New dispute shows No, No, A batched dispute, POS 23, TX pre-selected with a chip. | D9: Do first
A10: L09 | B10: Admin "Lists" view for users in the Admin list: rename, merge (move counts into another value), hide and reactivate values. | C10: adminListOptions(list) and adminUpdateOption(list, value, change) reject non-admins. Merge adds Count to the target and hides the source. | D10: Do next
A11: L10 | B11: Hidden values never show as suggestions. | C11: A hidden payer does not appear in the combo. Existing disputes keep their stored text. | D11: Do next
A12: L11 | B12: Typo protection: a typed value within edit distance 2 of an existing value (case-insensitive, punctuation ignored) shows "Did you mean …?" before it is saved as new. | C12: "SILVER ALLIANCE,LLC" prompts "Did you mean SILVER ALLIANCE LLC?". | D12: Do first
... A16: L15 | B16: setup() is idempotent for Options: it adds missing seed rows and never duplicates them. The 7 placeholder plan types are removed. | C16: Running setup() twice gives the same row count. | D16: Do first

Sheet Validation rules
A1: Rule ID | B1: Field(s) | C1: Rule | D1: Message | E1: Blocking/Warning | F1: Status
A2: V01 | B2: All required fields | C2: Not empty. | D2: <label> is required | E2: Blocking | F2: Existing
A3: V02 | B3: *_zip | C3: Accept 12345, 12345-6789 or 123456789. Store 12345 or 12345-6789. | D3: must look like 12345 or 12345-6789 | E3: Blocking | F3: Changed
A4: V03 | B4: *_phone, *_fax | C4: Accept (817) 566-1232, 817-566-1232 or 8175661232. Store and show as (817) 566-1232. | D4: must be a 10-digit phone number, like (817) 566-1232 | E4: Blocking | F4: Changed
A5: V04 | B5: *_email | C5: ^[^@\s]+@[^@\s]+\.[^@\s]+$ | D5: is not a valid email | E5: Blocking | F5: Existing
A6: V05 | B6: qpa, cost_sharing, initial_payment | C6: ^\d+(\.\d{1,2})?$ after removing $ , and spaces. | D6: must be an amount like 154.00 | E6: Blocking | F6: Existing
A7: V06 | B7: All date fields | C7: YYYY-MM-DD. | D7: must be a date | E7: Blocking | F7: Existing
A8: V07 | B8: service_date | C8: On or after 2022-01-01. | D8: must be on or after 2022-01-01 | E8: Blocking | F8: Existing
A9: V08 | B9: on_start_date | C9: Not in the future. | D9: cannot be in the future | E9: Blocking | F9: Existing
A10: V09 | B10: tin | C10: ^\d{9}$ | D10: Tax ID must be 9 digits | E10: Blocking | F10: New
A11: V10 | B11: npi | C11: ^\d{10}$ | D11: NPI must be 10 digits | E11: Blocking | F11: New
A12: V11 | B12: q_prior_2022 | C12: Yes stops the dispute. | D12: Not eligible for federal IDR | E12: Blocking | F12: New
... A38: V37 | B38: Line items (batching) | C38: Service dates on one batched dispute fall within a 30-business-day window. | D38: These lines may not be batched together | E38: Warning | F38: Planned

Sheet Workflow
A1: From status | B1: Action | C1: To status | D1: Who | E1: Required conditions | F1: Server function | G1: Log event
A2: (none) | B2: Save page 1 | C2: Draft | D2: Lebanon preparer | E2: None. A new DisputeID (IDR-yymmdd-XXXX) and Drive folder are created. | F2: saveDispute | G2: save
A3: Draft | B3: Save any page or line | C3: Draft | D3: Lebanon preparer | E3: Not Filed. Learn on save (L03). | F3: saveDispute, saveLine, deleteLine | G3: save, line:<n>
A4: Draft | B4: Upload or remove a file | C4: Draft | D4: Lebanon preparer | E4: Dispute saved; under 45 MB. | F4: uploadFile, removeFile | G4: upload, file-removed
A5: Draft | B5: Save & create confirmation PDF | C5: Ready for US desk | D5: Lebanon preparer | E5: No blocking rules (V01–V36), including eligibility (V11, V12) and deadline (V13). Warnings shown, not blocking. | F5: finalizeDispute | G5: status
A6: Ready for US desk | B6: Mark as filed | C6: Filed | D6: US desk (UsDeskUser) | E6: Portal number matches ^DISP-\d{7}$ and portal confirmation PDF attached (V28, V29). | F6: markFiled | G6: status
A7: Ready for US desk | B7: Return | C7: Returned | D7: US desk (UsDeskUser) | E7: Reason from ReturnReason (V30). Reason is learned. | F7: returnDispute | G7: status
A8: Ready for US desk | B8: Edit | C8: Ready for US desk | D8: Lebanon preparer | E8: Allowed in Code.gs today. Status does not change. See Open questions. | F8: saveDispute, saveLine | G8: save
A9: Returned | B9: Fix and save | C9: Returned | D9: Lebanon preparer | E9: Reason shown at the top. Status stays Returned until finalized. | F9: saveDispute, saveLine | G9: save
A10: Returned | B10: Save & create confirmation PDF | C10: Ready for US desk | D10: Lebanon preparer | E10: Same as Draft → Ready. ReturnReason is cleared. | F10: finalizeDispute | G10: status
A11: Filed | B11: (any edit) | C11: Filed | D11: Nobody | E11: Locked (V34). | F11: - | G11: -
A12: (any) | B12: Manage lists | C12: (no change) | D12: Admin | E12: User in the Admin list. Rename, merge, hide, reactivate. | F12: adminListOptions, adminUpdateOption | G12: admin
A13: (any) | B13: View insights | C13: (no change) | D13: Any user | E13: None. | F13: getInsights | G13: -

Sheet Data model
A1: Table | B1: Column | C1: Type | D1: Status | E1: Notes
A2: Disputes | B2: DisputeID | C2: text | D2: Existing | E2: Key. IDR-yymmdd-XXXX.
A3: Disputes | B3: Status | C3: text | D3: Existing | E3: Draft, Ready for US desk, Filed, Returned.
A4: Disputes | B4: Team | C4: text (combo) | D4: Existing | E4: Learned.
A5: Disputes | B5: Owner | C5: text (combo) | D5: Existing | E5: Learned.
A6: Disputes | B6: CreatedBy | C6: email | D6: Existing
A7: Disputes | B7: CreatedAt | C7: timestamp | D7: Existing | E7: yyyy-MM-dd HH:mm:ss
A8: Disputes | B8: UpdatedBy | C8: email | D8: Existing
A9: Disputes | B9: UpdatedAt | C9: timestamp | D9: Existing
A10: Disputes | B10: FolderUrl | C10: url | D10: Existing | E10: Drive folder of the dispute.
A11: Disputes | B11: ConfirmationPdfUrl | C11: url | D11: Existing
A12: Disputes | B12: ReadyAt | C12: timestamp | D12: Existing
A13: Disputes | B13: FiledBy | C13: email | D13: Existing
A14: Disputes | B14: FiledAt | C14: timestamp | D14: Existing
A15: Disputes | B15: PortalDisputeNumber | C15: text | D15: Existing | E15: ^DISP-\d{7}$
A16: Disputes | B16: PortalPdfUrl | C16: url | D16: Existing
A17: Disputes | B17: ReturnReason | C17: text (combo) | D17: Existing
A18: Disputes | B18: q_prior_2022 | C18: radio | D18: Existing | E18: Field. See Fields.
A19: Disputes | B19: q_acting_as | C19: radio | D19: Existing | E19: Field. See Fields.
A20: Disputes | B20: tin | C20: text | D20: New | E20: Field. See Fields.
A21: Disputes | B21: npi | C21: text | D21: New | E21: Field. See Fields.
A22: Disputes | B22: q_plan_type | C22: combo | D22: Existing | E22: Field. See Fields.
A23: Disputes | B23: dispute_kind | C23: radio | D23: New | E23: Field. See Fields.
A24: Disputes | B24: on_start_date | C24: date | D24: Existing | E24: Field. See Fields.
A25: Disputes | B25: consent_waiver | C25: radio | D25: Existing | E25: Field. See Fields.
A26: Disputes | B26: plan_role | C26: radio | D26: Existing | E26: Field. See Fields.
A27: Disputes | B27: plan_name | C27: combo | D27: Existing | E27: Field. See Fields.
A28: Disputes | B28: plan_addr1 | C28: text | D28: Existing | E28: Field. See Fields.
A29: Disputes | B29: plan_addr2 | C29: text | D29: Existing | E29: Field. See Fields.
... A94: LineItems | B94: location | C94: select | D94: Existing | E94: Field. See Fields.
A95: Files | B95: DisputeID | C95: text | D95: Existing
A96: Files | B96: Category | C96: text | D96: Existing | E96: on_evidence, qpa, additional, confirmation_pdf, portal_confirmation.
A97: Files | B97: LineNo | C97: number | D97: Existing | E97: For qpa files.
A98: Files | B98: Name | C98: text | D98: Existing
A99: Files | B99: Url | C99: url | D99: Existing
A100: Files | B100: FileId | C100: text | D100: Existing | E100: Drive file id.
A101: Files | B101: UploadedBy | C101: email | D101: Existing
A102: Files | B102: UploadedAt | C102: timestamp | D102: Existing
A103: Files | B103: ClaimNumber | C103: text | D103: New | E103: New (assumed). Lets one QPA file cover all lines with this claim number (V23).
A104: Options | B104: List | C104: text | D104: Existing | E104: List name, e.g. Payer.
...

Sheet API
A1: Function | B1: Visibility | C1: Status | D1: Inputs | E1: Outputs | F1: Purpose
A2: doGet | B2: Public | C2: Existing | D2: (none) | E2: HtmlOutput | F2: Serves Index.html with the bootstrap data inlined.
A3: getBootstrap | B3: Public | C3: Changed | D3: withList (boolean) | E3: {user, isUsDesk, isAdmin, schema, options, defaults, settings, status, listFilter?, list?} | F3: First screen data. v2 adds isAdmin, defaults (suggestDefaults_) and settings; options carry label, data, count.
A4: listDisputes | B4: Public | C4: Existing | D4: filter (status or "All") | E4: [{id, status, team, owner, plan, lines, updatedAt, updatedBy, returnReason, pdf}] | F4: Dispute list, newest first.
A5: getDispute | B5: Public | C5: Existing | D5: id | E5: {dispute, lines, files} | F5: Everything for one dispute in one read.
A6: saveDispute | B6: Public | C6: Changed | D6: payload {id?, page, values} | E6: {id, bundle} | F6: Creates or updates the header. v2 calls learn_ for combo values.
A7: saveLine | B7: Public | C7: Changed | D7: id, lineNo?, values | E7: {lineNo, bundle} | F7: Adds or replaces a line. v2 calls learn_.
A8: deleteLine | B8: Public | C8: Existing | D8: id, lineNo | E8: bundle | F8: Deletes a line and its QPA file records.
A9: uploadFile | B9: Public | C9: Existing | D9: id, category, lineNo, name, mimeType, data (base64) | E9: {name, url, id, files} | F9: Stores a file in the dispute folder.
A10: removeFile | B10: Public | C10: Existing | D10: id, fileId | E10: files | F10: Removes a file record and trashes the file.
A11: finalizeDispute | B11: Public | C11: Changed | D11: id | E11: {ok, problems?, warnings?, pdfUrl?, bundle?} | F11: Validates and creates the confirmation PDF; status Ready. v2 adds warnings and new blocking rules.
A12: markFiled | B12: Public | C12: Changed | D12: id, portalNumber, portalPdf {name, mimeType, data} | E12: bundle | F12: US desk only. v2 requires ^DISP-\d{7}$ and the PDF.
... A35: demoUseLebanonView / demoUseUsView | B35: Public (DemoData.gs) | C35: Existing | D35: (none) | E35: (none) | F35: Switches the demo user on or off the US desk.

Sheet Backlog
A1: ID | B1: Source | C1: User story | D1: Priority | E1: Effort (S/M/L) | F1: Acceptance criteria
A2: B01 | B2: FR-1 | C2: As a preparer, I pick the payer from a list so the address, email, phone and fax fill in. | D2: Do first | E2: M | F2: Payer combo fills 8 plan fields from Payer Data. Only empty fields filled. New payers are learned.
A3: B02 | B3: FR-2 | C3: As a preparer, I pick our billing entity so provider details, TIN and NPI fill in. | D3: Do first | E3: S | F3: BillingEntity combo fills q_acting_as, tin, npi, prov_designation, prov_group_name, provider contact.
A4: B03 | B4: FR-3 | C4: As a preparer, I see smart defaults I can change. | D4: Do first | E4: S | F4: No, No, A batched dispute, Emergency, POS 23, TX, third party No pre-selected with a "default" chip.
A5: B04 | B5: FR-4 | C5: As a preparer, I see the deadline and days left under the open negotiation start date. | D5: Do first | E5: M | F5: businessDeadline_ gives 10/15 and 10/21 for a 09/01/2026 start. Red at 1 day or less; Ready blocked when passed. US desk queue sorts by deadline.
A6: B05 | B6: FR-5 | C6: As a preparer, I am stopped when a dispute is not eligible. | D6: Do first | E6: S | F6: Yes on prior-2022 or consent shows "Not eligible for federal IDR" and blocks Ready.
A7: B06 | B7: FR-6 | C7: As a preparer, I pick a real Health Plan Type. | D7: Do first | E7: S | F7: Placeholders removed; observed value seeded; new values learned. Needs the full portal list.
A8: B07 | B8: FR-7 | C8: As a preparer, I am warned when a claim number is already in another dispute. | D8: Do next | E8: S | F8: Warning names the other dispute when it is not Returned.
A9: B08 | B9: FR-8 | C9: As a preparer, I am warned when lines cannot be batched together. | D9: Do next | E9: M | F9: Warning when service dates fall outside a 30-business-day window (V37). Rules need business sign-off.
A10: B09 | B10: FR-9 | C10: As a preparer, I duplicate a line and change only what differs. | D10: Do next | E10: S | F10: "Duplicate line" copies all fields. "Add line" copies claim number, date, QPA doc, item type, POS and location.
A11: B10 | B11: FR-10 | C11: As a preparer, I pick service codes, modifiers and POS codes from lists. | D11: Do next | E11: S | F11: Combos seeded from Lists; picking a code fills description; free text kept.
A12: B11 | B12: FR-11 | C12: As the US desk, I pick a return reason from a list. | D12: Do next | E12: S | F12: ReturnReason combo; returns can be counted by reason.
... A33: B32 | B33: Spec v2 §5 | C33: As a demo user, demo data uses the seeded payers and entities. | D33: Do next | E33: S | F33: DemoData stays synthetic, no real claim numbers; Insights show trends.

Sheet Open questions
A1: ID | B1: Topic | C1: Question | D1: Owner | E1: Status
A2: Q01 | B2: US desk users | C2: Who are the US desk users? We need their emails for the UsDeskUser list. | D2: Business | E2: Open
A3: Q02 | B3: Admins | C3: Who can manage lists in the Lists view? We need emails for the Admin list. | D3: Business | E3: Open
A4: Q03 | B4: Health Plan Type | C4: What other Health Plan Type options does the portal show? Only one was seen on the 4 notices. | D4: Business / US desk | E4: Open
A5: Q04 | B5: Bundled disputes | C5: When do we use "A bundled dispute"? What rules apply to its lines? | D5: Business | E5: Open
A6: Q05 | B6: Batching rules | C6: Which batching rules should the Studio check (same payer, same service code, 30-business-day window)? | D6: Business | E6: Open
A7: Q06 | B7: Teams and Owners | C7: Should Team and Owner have seed values, or only be learned? | D7: Business | E7: Open
A8: Q07 | B8: Modifiers | C8: Confirm that Service Code Modifier(s) is optional. It is required in the app today but empty on every notice. | D8: US desk | E8: Open
A9: Q08 | B9: Editing Ready disputes | C9: Should an edit to a Ready dispute move it back to Draft? Today it stays Ready. | D9: Business | E9: Open
A10: Q09 | B10: Data quality | C10: DISP-7998956 lines 2–11 have no claim number, date, QPA, POS or location. Was the dispute filed that way? Does it need a fix on the portal? | D10: US desk | E10: Open
A11: Q10 | B11: Deadline time zone | C11: Which time zone sets the deadline day (Central for the facility)? | D11: Business | E11: Open
A12: Q11 | B12: Holidays | C12: Confirm the federal holiday list for 2026 and 2027. Who adds 2028? | D12: IT | E12: Open
... A18: Q17 | B18: Options Note column | C18: Keep the old Options Note column, or move its text into Label? | D18: IT | E18: Open
